[2025-04-14T14:29:23.841+0000] {local_task_job_runner.py:123} INFO - ::group::Pre task execution logs
[2025-04-14T14:29:23.860+0000] {taskinstance.py:2614} INFO - Dependencies all met for dep_context=non-requeueable deps ti=<TaskInstance: dbt_airflow_example.run_dbt_staging manual__2025-04-14T14:21:35.452685+00:00 [queued]>
[2025-04-14T14:29:23.870+0000] {taskinstance.py:2614} INFO - Dependencies all met for dep_context=requeueable deps ti=<TaskInstance: dbt_airflow_example.run_dbt_staging manual__2025-04-14T14:21:35.452685+00:00 [queued]>
[2025-04-14T14:29:23.870+0000] {taskinstance.py:2867} INFO - Starting attempt 5 of 6
[2025-04-14T14:29:23.884+0000] {taskinstance.py:2890} INFO - Executing <Task(BashOperator): run_dbt_staging> on 2025-04-14 14:21:35.452685+00:00
[2025-04-14T14:29:23.891+0000] {standard_task_runner.py:104} INFO - Running: ['***', 'tasks', 'run', 'dbt_***_example', 'run_dbt_staging', 'manual__2025-04-14T14:21:35.452685+00:00', '--job-id', '459', '--raw', '--subdir', 'DAGS_FOLDER/run_dbt_model.py', '--cfg-path', '/tmp/tmpgjilzrny']
[2025-04-14T14:29:23.893+0000] {standard_task_runner.py:105} INFO - Job 459: Subtask run_dbt_staging
[2025-04-14T14:29:23.895+0000] {logging_mixin.py:190} WARNING - /home/***/.local/lib/python3.12/site-packages/***/task/task_runner/standard_task_runner.py:70 DeprecationWarning: This process (pid=4304) is multi-threaded, use of fork() may lead to deadlocks in the child.
[2025-04-14T14:29:23.896+0000] {standard_task_runner.py:72} INFO - Started process 4307 to run task
[2025-04-14T14:29:23.942+0000] {task_command.py:467} INFO - Running <TaskInstance: dbt_airflow_example.run_dbt_staging manual__2025-04-14T14:21:35.452685+00:00 [running]> on host b7be566335ce
[2025-04-14T14:29:24.029+0000] {taskinstance.py:3134} INFO - Exporting env vars: AIRFLOW_CTX_DAG_OWNER='***' AIRFLOW_CTX_DAG_ID='dbt_***_example' AIRFLOW_CTX_TASK_ID='run_dbt_staging' AIRFLOW_CTX_EXECUTION_DATE='2025-04-14T14:21:35.452685+00:00' AIRFLOW_CTX_TRY_NUMBER='5' AIRFLOW_CTX_DAG_RUN_ID='manual__2025-04-14T14:21:35.452685+00:00'
[2025-04-14T14:29:24.030+0000] {taskinstance.py:732} INFO - ::endgroup::
[2025-04-14T14:29:24.051+0000] {subprocess.py:78} INFO - Tmp dir root location: /tmp
[2025-04-14T14:29:24.052+0000] {subprocess.py:88} INFO - Running command: ['/usr/bin/bash', '-c', 'cd /opt/***/dbt && dbt run --models stg_flights']
[2025-04-14T14:29:24.062+0000] {subprocess.py:99} INFO - Output:
[2025-04-14T14:29:29.389+0000] {subprocess.py:106} INFO - [0m14:29:29  Running with dbt=1.7.9
[2025-04-14T14:29:31.347+0000] {subprocess.py:106} INFO - [0m14:29:31  Encountered an error:
[2025-04-14T14:29:31.347+0000] {subprocess.py:106} INFO - Runtime Error
[2025-04-14T14:29:31.348+0000] {subprocess.py:106} INFO -   Credentials in profile "my_profile", target "dev" invalid: Runtime Error
[2025-04-14T14:29:31.349+0000] {subprocess.py:106} INFO -     Must specify authentication method
[2025-04-14T14:29:32.664+0000] {subprocess.py:110} INFO - Command exited with return code 2
[2025-04-14T14:29:32.678+0000] {taskinstance.py:3313} ERROR - Task failed with exception
Traceback (most recent call last):
  File "/home/airflow/.local/lib/python3.12/site-packages/airflow/models/taskinstance.py", line 768, in _execute_task
    result = _execute_callable(context=context, **execute_callable_kwargs)
             ^^^^^^^^^^^^^^^^^^^^^^^^^^^^^^^^^^^^^^^^^^^^^^^^^^^^^^^^^^^^^
  File "/home/airflow/.local/lib/python3.12/site-packages/airflow/models/taskinstance.py", line 734, in _execute_callable
    return ExecutionCallableRunner(
           ^^^^^^^^^^^^^^^^^^^^^^^^
  File "/home/airflow/.local/lib/python3.12/site-packages/airflow/utils/operator_helpers.py", line 252, in run
    return self.func(*args, **kwargs)
           ^^^^^^^^^^^^^^^^^^^^^^^^^^
  File "/home/airflow/.local/lib/python3.12/site-packages/airflow/models/baseoperator.py", line 424, in wrapper
    return func(self, *args, **kwargs)
           ^^^^^^^^^^^^^^^^^^^^^^^^^^^
  File "/home/airflow/.local/lib/python3.12/site-packages/airflow/operators/bash.py", line 276, in execute
    raise AirflowException(
airflow.exceptions.AirflowException: Bash command failed. The command returned a non-zero exit code 2.
[2025-04-14T14:29:32.686+0000] {taskinstance.py:1226} INFO - Marking task as UP_FOR_RETRY. dag_id=dbt_***_example, task_id=run_dbt_staging, run_id=manual__2025-04-14T14:21:35.452685+00:00, execution_date=20250414T142135, start_date=20250414T142923, end_date=20250414T142932
[2025-04-14T14:29:32.715+0000] {taskinstance.py:341} INFO - ::group::Post task execution logs
[2025-04-14T14:29:32.716+0000] {standard_task_runner.py:124} ERROR - Failed to execute job 459 for task run_dbt_staging (Bash command failed. The command returned a non-zero exit code 2.; 4307)
Traceback (most recent call last):
  File "/home/airflow/.local/lib/python3.12/site-packages/airflow/task/task_runner/standard_task_runner.py", line 117, in _start_by_fork
    ret = args.func(args, dag=self.dag)
          ^^^^^^^^^^^^^^^^^^^^^^^^^^^^^
  File "/home/airflow/.local/lib/python3.12/site-packages/airflow/cli/cli_config.py", line 49, in command
    return func(*args, **kwargs)
           ^^^^^^^^^^^^^^^^^^^^^
  File "/home/airflow/.local/lib/python3.12/site-packages/airflow/utils/cli.py", line 116, in wrapper
    return f(*args, **kwargs)
           ^^^^^^^^^^^^^^^^^^
  File "/home/airflow/.local/lib/python3.12/site-packages/airflow/cli/commands/task_command.py", line 483, in task_run
    task_return_code = _run_task_by_selected_method(args, _dag, ti)
                       ^^^^^^^^^^^^^^^^^^^^^^^^^^^^^^^^^^^^^^^^^^^^
  File "/home/airflow/.local/lib/python3.12/site-packages/airflow/cli/commands/task_command.py", line 256, in _run_task_by_selected_method
    return _run_raw_task(args, ti)
           ^^^^^^^^^^^^^^^^^^^^^^^
  File "/home/airflow/.local/lib/python3.12/site-packages/airflow/cli/commands/task_command.py", line 341, in _run_raw_task
    return ti._run_raw_task(
           ^^^^^^^^^^^^^^^^^
  File "/home/airflow/.local/lib/python3.12/site-packages/airflow/utils/session.py", line 97, in wrapper
    return func(*args, session=session, **kwargs)
           ^^^^^^^^^^^^^^^^^^^^^^^^^^^^^^^^^^^^^^
  File "/home/airflow/.local/lib/python3.12/site-packages/airflow/models/taskinstance.py", line 3006, in _run_raw_task
    return _run_raw_task(
           ^^^^^^^^^^^^^^
  File "/home/airflow/.local/lib/python3.12/site-packages/airflow/models/taskinstance.py", line 274, in _run_raw_task
    TaskInstance._execute_task_with_callbacks(
  File "/home/airflow/.local/lib/python3.12/site-packages/airflow/models/taskinstance.py", line 3161, in _execute_task_with_callbacks
    result = self._execute_task(context, task_orig)
             ^^^^^^^^^^^^^^^^^^^^^^^^^^^^^^^^^^^^^^
  File "/home/airflow/.local/lib/python3.12/site-packages/airflow/models/taskinstance.py", line 3185, in _execute_task
    return _execute_task(self, context, task_orig)
           ^^^^^^^^^^^^^^^^^^^^^^^^^^^^^^^^^^^^^^^
  File "/home/airflow/.local/lib/python3.12/site-packages/airflow/models/taskinstance.py", line 768, in _execute_task
    result = _execute_callable(context=context, **execute_callable_kwargs)
             ^^^^^^^^^^^^^^^^^^^^^^^^^^^^^^^^^^^^^^^^^^^^^^^^^^^^^^^^^^^^^
  File "/home/airflow/.local/lib/python3.12/site-packages/airflow/models/taskinstance.py", line 734, in _execute_callable
    return ExecutionCallableRunner(
           ^^^^^^^^^^^^^^^^^^^^^^^^
  File "/home/airflow/.local/lib/python3.12/site-packages/airflow/utils/operator_helpers.py", line 252, in run
    return self.func(*args, **kwargs)
           ^^^^^^^^^^^^^^^^^^^^^^^^^^
  File "/home/airflow/.local/lib/python3.12/site-packages/airflow/models/baseoperator.py", line 424, in wrapper
    return func(self, *args, **kwargs)
           ^^^^^^^^^^^^^^^^^^^^^^^^^^^
  File "/home/airflow/.local/lib/python3.12/site-packages/airflow/operators/bash.py", line 276, in execute
    raise AirflowException(
airflow.exceptions.AirflowException: Bash command failed. The command returned a non-zero exit code 2.
[2025-04-14T14:29:32.758+0000] {local_task_job_runner.py:266} INFO - Task exited with return code 1
[2025-04-14T14:29:32.778+0000] {taskinstance.py:3901} INFO - 0 downstream tasks scheduled from follow-on schedule check
[2025-04-14T14:29:32.781+0000] {local_task_job_runner.py:245} INFO - ::endgroup::
