[2025-04-14T14:26:34.926+0000] {local_task_job_runner.py:123} INFO - ::group::Pre task execution logs
[2025-04-14T14:26:34.964+0000] {taskinstance.py:2614} INFO - Dependencies all met for dep_context=non-requeueable deps ti=<TaskInstance: dbt_airflow_example.run_dbt_staging manual__2025-04-14T14:21:35.452685+00:00 [queued]>
[2025-04-14T14:26:34.979+0000] {taskinstance.py:2614} INFO - Dependencies all met for dep_context=requeueable deps ti=<TaskInstance: dbt_airflow_example.run_dbt_staging manual__2025-04-14T14:21:35.452685+00:00 [queued]>
[2025-04-14T14:26:34.979+0000] {taskinstance.py:2867} INFO - Starting attempt 2 of 3
[2025-04-14T14:26:35.000+0000] {taskinstance.py:2890} INFO - Executing <Task(BashOperator): run_dbt_staging> on 2025-04-14 14:21:35.452685+00:00
[2025-04-14T14:26:35.012+0000] {standard_task_runner.py:104} INFO - Running: ['***', 'tasks', 'run', 'dbt_***_example', 'run_dbt_staging', 'manual__2025-04-14T14:21:35.452685+00:00', '--job-id', '456', '--raw', '--subdir', 'DAGS_FOLDER/run_dbt_model.py', '--cfg-path', '/tmp/tmpkliw1hcd']
[2025-04-14T14:26:35.016+0000] {standard_task_runner.py:105} INFO - Job 456: Subtask run_dbt_staging
[2025-04-14T14:26:35.018+0000] {logging_mixin.py:190} WARNING - /home/***/.local/lib/python3.12/site-packages/***/task/task_runner/standard_task_runner.py:70 DeprecationWarning: This process (pid=4171) is multi-threaded, use of fork() may lead to deadlocks in the child.
[2025-04-14T14:26:35.021+0000] {standard_task_runner.py:72} INFO - Started process 4172 to run task
[2025-04-14T14:26:35.091+0000] {task_command.py:467} INFO - Running <TaskInstance: dbt_airflow_example.run_dbt_staging manual__2025-04-14T14:21:35.452685+00:00 [running]> on host b7be566335ce
[2025-04-14T14:26:35.249+0000] {taskinstance.py:3134} INFO - Exporting env vars: AIRFLOW_CTX_DAG_OWNER='***' AIRFLOW_CTX_DAG_ID='dbt_***_example' AIRFLOW_CTX_TASK_ID='run_dbt_staging' AIRFLOW_CTX_EXECUTION_DATE='2025-04-14T14:21:35.452685+00:00' AIRFLOW_CTX_TRY_NUMBER='2' AIRFLOW_CTX_DAG_RUN_ID='manual__2025-04-14T14:21:35.452685+00:00'
[2025-04-14T14:26:35.251+0000] {taskinstance.py:732} INFO - ::endgroup::
[2025-04-14T14:26:35.281+0000] {subprocess.py:78} INFO - Tmp dir root location: /tmp
[2025-04-14T14:26:35.290+0000] {subprocess.py:88} INFO - Running command: ['/usr/bin/bash', '-c', 'cd dbt && dbt run --models stg_flights']
[2025-04-14T14:26:35.304+0000] {subprocess.py:99} INFO - Output:
[2025-04-14T14:26:35.306+0000] {subprocess.py:106} INFO - /usr/bin/bash: line 1: cd: dbt: No such file or directory
[2025-04-14T14:26:35.307+0000] {subprocess.py:110} INFO - Command exited with return code 1
[2025-04-14T14:26:35.331+0000] {taskinstance.py:3313} ERROR - Task failed with exception
Traceback (most recent call last):
  File "/home/airflow/.local/lib/python3.12/site-packages/airflow/models/taskinstance.py", line 768, in _execute_task
    result = _execute_callable(context=context, **execute_callable_kwargs)
             ^^^^^^^^^^^^^^^^^^^^^^^^^^^^^^^^^^^^^^^^^^^^^^^^^^^^^^^^^^^^^
  File "/home/airflow/.local/lib/python3.12/site-packages/airflow/models/taskinstance.py", line 734, in _execute_callable
    return ExecutionCallableRunner(
           ^^^^^^^^^^^^^^^^^^^^^^^^
  File "/home/airflow/.local/lib/python3.12/site-packages/airflow/utils/operator_helpers.py", line 252, in run
    return self.func(*args, **kwargs)
           ^^^^^^^^^^^^^^^^^^^^^^^^^^
  File "/home/airflow/.local/lib/python3.12/site-packages/airflow/models/baseoperator.py", line 424, in wrapper
    return func(self, *args, **kwargs)
           ^^^^^^^^^^^^^^^^^^^^^^^^^^^
  File "/home/airflow/.local/lib/python3.12/site-packages/airflow/operators/bash.py", line 276, in execute
    raise AirflowException(
airflow.exceptions.AirflowException: Bash command failed. The command returned a non-zero exit code 1.
[2025-04-14T14:26:35.349+0000] {taskinstance.py:1226} INFO - Marking task as UP_FOR_RETRY. dag_id=dbt_***_example, task_id=run_dbt_staging, run_id=manual__2025-04-14T14:21:35.452685+00:00, execution_date=20250414T142135, start_date=20250414T142634, end_date=20250414T142635
[2025-04-14T14:26:35.407+0000] {taskinstance.py:341} INFO - ::group::Post task execution logs
[2025-04-14T14:26:35.409+0000] {standard_task_runner.py:124} ERROR - Failed to execute job 456 for task run_dbt_staging (Bash command failed. The command returned a non-zero exit code 1.; 4172)
Traceback (most recent call last):
  File "/home/airflow/.local/lib/python3.12/site-packages/airflow/task/task_runner/standard_task_runner.py", line 117, in _start_by_fork
    ret = args.func(args, dag=self.dag)
          ^^^^^^^^^^^^^^^^^^^^^^^^^^^^^
  File "/home/airflow/.local/lib/python3.12/site-packages/airflow/cli/cli_config.py", line 49, in command
    return func(*args, **kwargs)
           ^^^^^^^^^^^^^^^^^^^^^
  File "/home/airflow/.local/lib/python3.12/site-packages/airflow/utils/cli.py", line 116, in wrapper
    return f(*args, **kwargs)
           ^^^^^^^^^^^^^^^^^^
  File "/home/airflow/.local/lib/python3.12/site-packages/airflow/cli/commands/task_command.py", line 483, in task_run
    task_return_code = _run_task_by_selected_method(args, _dag, ti)
                       ^^^^^^^^^^^^^^^^^^^^^^^^^^^^^^^^^^^^^^^^^^^^
  File "/home/airflow/.local/lib/python3.12/site-packages/airflow/cli/commands/task_command.py", line 256, in _run_task_by_selected_method
    return _run_raw_task(args, ti)
           ^^^^^^^^^^^^^^^^^^^^^^^
  File "/home/airflow/.local/lib/python3.12/site-packages/airflow/cli/commands/task_command.py", line 341, in _run_raw_task
    return ti._run_raw_task(
           ^^^^^^^^^^^^^^^^^
  File "/home/airflow/.local/lib/python3.12/site-packages/airflow/utils/session.py", line 97, in wrapper
    return func(*args, session=session, **kwargs)
           ^^^^^^^^^^^^^^^^^^^^^^^^^^^^^^^^^^^^^^
  File "/home/airflow/.local/lib/python3.12/site-packages/airflow/models/taskinstance.py", line 3006, in _run_raw_task
    return _run_raw_task(
           ^^^^^^^^^^^^^^
  File "/home/airflow/.local/lib/python3.12/site-packages/airflow/models/taskinstance.py", line 274, in _run_raw_task
    TaskInstance._execute_task_with_callbacks(
  File "/home/airflow/.local/lib/python3.12/site-packages/airflow/models/taskinstance.py", line 3161, in _execute_task_with_callbacks
    result = self._execute_task(context, task_orig)
             ^^^^^^^^^^^^^^^^^^^^^^^^^^^^^^^^^^^^^^
  File "/home/airflow/.local/lib/python3.12/site-packages/airflow/models/taskinstance.py", line 3185, in _execute_task
    return _execute_task(self, context, task_orig)
           ^^^^^^^^^^^^^^^^^^^^^^^^^^^^^^^^^^^^^^^
  File "/home/airflow/.local/lib/python3.12/site-packages/airflow/models/taskinstance.py", line 768, in _execute_task
    result = _execute_callable(context=context, **execute_callable_kwargs)
             ^^^^^^^^^^^^^^^^^^^^^^^^^^^^^^^^^^^^^^^^^^^^^^^^^^^^^^^^^^^^^
  File "/home/airflow/.local/lib/python3.12/site-packages/airflow/models/taskinstance.py", line 734, in _execute_callable
    return ExecutionCallableRunner(
           ^^^^^^^^^^^^^^^^^^^^^^^^
  File "/home/airflow/.local/lib/python3.12/site-packages/airflow/utils/operator_helpers.py", line 252, in run
    return self.func(*args, **kwargs)
           ^^^^^^^^^^^^^^^^^^^^^^^^^^
  File "/home/airflow/.local/lib/python3.12/site-packages/airflow/models/baseoperator.py", line 424, in wrapper
    return func(self, *args, **kwargs)
           ^^^^^^^^^^^^^^^^^^^^^^^^^^^
  File "/home/airflow/.local/lib/python3.12/site-packages/airflow/operators/bash.py", line 276, in execute
    raise AirflowException(
airflow.exceptions.AirflowException: Bash command failed. The command returned a non-zero exit code 1.
[2025-04-14T14:26:35.439+0000] {local_task_job_runner.py:266} INFO - Task exited with return code 1
[2025-04-14T14:26:35.488+0000] {taskinstance.py:3901} INFO - 0 downstream tasks scheduled from follow-on schedule check
[2025-04-14T14:26:35.493+0000] {local_task_job_runner.py:245} INFO - ::endgroup::
