[2025-04-14T17:25:56.556+0000] {local_task_job_runner.py:123} INFO - ::group::Pre task execution logs
[2025-04-14T17:25:56.582+0000] {taskinstance.py:2614} INFO - Dependencies all met for dep_context=non-requeueable deps ti=<TaskInstance: dbt_airflow.run_dbt_core manual__2025-04-14T15:18:53.940263+00:00 [queued]>
[2025-04-14T17:25:56.593+0000] {taskinstance.py:2614} INFO - Dependencies all met for dep_context=requeueable deps ti=<TaskInstance: dbt_airflow.run_dbt_core manual__2025-04-14T15:18:53.940263+00:00 [queued]>
[2025-04-14T17:25:56.594+0000] {taskinstance.py:2867} INFO - Starting attempt 13 of 14
[2025-04-14T17:25:56.608+0000] {taskinstance.py:2890} INFO - Executing <Task(BashOperator): run_dbt_core> on 2025-04-14 15:18:53.940263+00:00
[2025-04-14T17:25:56.618+0000] {logging_mixin.py:190} WARNING - /home/***/.local/lib/python3.12/site-packages/***/task/task_runner/standard_task_runner.py:70 DeprecationWarning: This process (pid=14161) is multi-threaded, use of fork() may lead to deadlocks in the child.
[2025-04-14T17:25:56.616+0000] {standard_task_runner.py:104} INFO - Running: ['***', 'tasks', 'run', 'dbt_***', 'run_dbt_core', 'manual__2025-04-14T15:18:53.940263+00:00', '--job-id', '520', '--raw', '--subdir', 'DAGS_FOLDER/run_dbt_model.py', '--cfg-path', '/tmp/tmpzoeo3o8p']
[2025-04-14T17:25:56.619+0000] {standard_task_runner.py:72} INFO - Started process 14162 to run task
[2025-04-14T17:25:56.619+0000] {standard_task_runner.py:105} INFO - Job 520: Subtask run_dbt_core
[2025-04-14T17:25:56.667+0000] {task_command.py:467} INFO - Running <TaskInstance: dbt_airflow.run_dbt_core manual__2025-04-14T15:18:53.940263+00:00 [running]> on host b7be566335ce
[2025-04-14T17:25:56.750+0000] {taskinstance.py:3134} INFO - Exporting env vars: AIRFLOW_CTX_DAG_OWNER='***' AIRFLOW_CTX_DAG_ID='dbt_***' AIRFLOW_CTX_TASK_ID='run_dbt_core' AIRFLOW_CTX_EXECUTION_DATE='2025-04-14T15:18:53.940263+00:00' AIRFLOW_CTX_TRY_NUMBER='13' AIRFLOW_CTX_DAG_RUN_ID='manual__2025-04-14T15:18:53.940263+00:00'
[2025-04-14T17:25:56.751+0000] {taskinstance.py:732} INFO - ::endgroup::
[2025-04-14T17:25:56.767+0000] {subprocess.py:78} INFO - Tmp dir root location: /tmp
[2025-04-14T17:25:56.768+0000] {subprocess.py:88} INFO - Running command: ['/usr/bin/bash', '-c', 'cd /opt/***/dbt && dbt run --models core_flights']
[2025-04-14T17:25:56.778+0000] {subprocess.py:99} INFO - Output:
[2025-04-14T17:26:00.249+0000] {subprocess.py:106} INFO - [0m17:26:00  Running with dbt=1.7.9
[2025-04-14T17:26:01.819+0000] {subprocess.py:106} INFO - [0m17:26:01  Registered adapter: bigquery=1.7.9
[2025-04-14T17:26:02.825+0000] {subprocess.py:106} INFO - [0m17:26:02  Found 1 seed, 3 models, 1 source, 0 exposures, 0 metrics, 571 macros, 0 groups, 0 semantic models
[2025-04-14T17:26:02.829+0000] {subprocess.py:106} INFO - [0m17:26:02
[2025-04-14T17:26:03.569+0000] {subprocess.py:106} INFO - [0m17:26:03  Concurrency: 1 threads (target='dev')
[2025-04-14T17:26:03.570+0000] {subprocess.py:106} INFO - [0m17:26:03
[2025-04-14T17:26:03.605+0000] {subprocess.py:106} INFO - [0m17:26:03  1 of 1 START sql table model db_project_dataset.core_flights ................... [RUN]
[2025-04-14T17:26:06.707+0000] {subprocess.py:106} INFO - [0m17:26:06  BigQuery adapter: https://console.cloud.google.com/bigquery?project=db-project-456518&j=bq:europe-central2:de89dfa1-6434-4c46-aed4-0a1caf8b2c37&page=queryresults
[2025-04-14T17:26:06.724+0000] {subprocess.py:106} INFO - [0m17:26:06  1 of 1 ERROR creating sql table model db_project_dataset.core_flights .......... [[31mERROR[0m in 3.12s]
[2025-04-14T17:26:06.732+0000] {subprocess.py:106} INFO - [0m17:26:06
[2025-04-14T17:26:06.734+0000] {subprocess.py:106} INFO - [0m17:26:06  Finished running 1 table model in 0 hours 0 minutes and 3.90 seconds (3.90s).
[2025-04-14T17:26:06.761+0000] {subprocess.py:106} INFO - [0m17:26:06
[2025-04-14T17:26:06.762+0000] {subprocess.py:106} INFO - [0m17:26:06  [31mCompleted with 1 error and 0 warnings:[0m
[2025-04-14T17:26:06.763+0000] {subprocess.py:106} INFO - [0m17:26:06
[2025-04-14T17:26:06.764+0000] {subprocess.py:106} INFO - [0m17:26:06    Database Error in model core_flights (models/core/core_flights.sql)
[2025-04-14T17:26:06.765+0000] {subprocess.py:106} INFO -   Failed to parse input string "1991-08-09 90:2."
[2025-04-14T17:26:06.765+0000] {subprocess.py:106} INFO -   compiled Code at target/run/flights_project/models/core/core_flights.sql
[2025-04-14T17:26:06.766+0000] {subprocess.py:106} INFO - [0m17:26:06
[2025-04-14T17:26:06.766+0000] {subprocess.py:106} INFO - [0m17:26:06  Done. PASS=0 WARN=0 ERROR=1 SKIP=0 TOTAL=1
[2025-04-14T17:26:07.809+0000] {subprocess.py:110} INFO - Command exited with return code 1
[2025-04-14T17:26:07.821+0000] {taskinstance.py:3313} ERROR - Task failed with exception
Traceback (most recent call last):
  File "/home/airflow/.local/lib/python3.12/site-packages/airflow/models/taskinstance.py", line 768, in _execute_task
    result = _execute_callable(context=context, **execute_callable_kwargs)
             ^^^^^^^^^^^^^^^^^^^^^^^^^^^^^^^^^^^^^^^^^^^^^^^^^^^^^^^^^^^^^
  File "/home/airflow/.local/lib/python3.12/site-packages/airflow/models/taskinstance.py", line 734, in _execute_callable
    return ExecutionCallableRunner(
           ^^^^^^^^^^^^^^^^^^^^^^^^
  File "/home/airflow/.local/lib/python3.12/site-packages/airflow/utils/operator_helpers.py", line 252, in run
    return self.func(*args, **kwargs)
           ^^^^^^^^^^^^^^^^^^^^^^^^^^
  File "/home/airflow/.local/lib/python3.12/site-packages/airflow/models/baseoperator.py", line 424, in wrapper
    return func(self, *args, **kwargs)
           ^^^^^^^^^^^^^^^^^^^^^^^^^^^
  File "/home/airflow/.local/lib/python3.12/site-packages/airflow/operators/bash.py", line 276, in execute
    raise AirflowException(
airflow.exceptions.AirflowException: Bash command failed. The command returned a non-zero exit code 1.
[2025-04-14T17:26:07.828+0000] {taskinstance.py:1226} INFO - Marking task as UP_FOR_RETRY. dag_id=dbt_***, task_id=run_dbt_core, run_id=manual__2025-04-14T15:18:53.940263+00:00, execution_date=20250414T151853, start_date=20250414T172556, end_date=20250414T172607
[2025-04-14T17:26:07.863+0000] {taskinstance.py:341} INFO - ::group::Post task execution logs
[2025-04-14T17:26:07.864+0000] {standard_task_runner.py:124} ERROR - Failed to execute job 520 for task run_dbt_core (Bash command failed. The command returned a non-zero exit code 1.; 14162)
Traceback (most recent call last):
  File "/home/airflow/.local/lib/python3.12/site-packages/airflow/task/task_runner/standard_task_runner.py", line 117, in _start_by_fork
    ret = args.func(args, dag=self.dag)
          ^^^^^^^^^^^^^^^^^^^^^^^^^^^^^
  File "/home/airflow/.local/lib/python3.12/site-packages/airflow/cli/cli_config.py", line 49, in command
    return func(*args, **kwargs)
           ^^^^^^^^^^^^^^^^^^^^^
  File "/home/airflow/.local/lib/python3.12/site-packages/airflow/utils/cli.py", line 116, in wrapper
    return f(*args, **kwargs)
           ^^^^^^^^^^^^^^^^^^
  File "/home/airflow/.local/lib/python3.12/site-packages/airflow/cli/commands/task_command.py", line 483, in task_run
    task_return_code = _run_task_by_selected_method(args, _dag, ti)
                       ^^^^^^^^^^^^^^^^^^^^^^^^^^^^^^^^^^^^^^^^^^^^
  File "/home/airflow/.local/lib/python3.12/site-packages/airflow/cli/commands/task_command.py", line 256, in _run_task_by_selected_method
    return _run_raw_task(args, ti)
           ^^^^^^^^^^^^^^^^^^^^^^^
  File "/home/airflow/.local/lib/python3.12/site-packages/airflow/cli/commands/task_command.py", line 341, in _run_raw_task
    return ti._run_raw_task(
           ^^^^^^^^^^^^^^^^^
  File "/home/airflow/.local/lib/python3.12/site-packages/airflow/utils/session.py", line 97, in wrapper
    return func(*args, session=session, **kwargs)
           ^^^^^^^^^^^^^^^^^^^^^^^^^^^^^^^^^^^^^^
  File "/home/airflow/.local/lib/python3.12/site-packages/airflow/models/taskinstance.py", line 3006, in _run_raw_task
    return _run_raw_task(
           ^^^^^^^^^^^^^^
  File "/home/airflow/.local/lib/python3.12/site-packages/airflow/models/taskinstance.py", line 274, in _run_raw_task
    TaskInstance._execute_task_with_callbacks(
  File "/home/airflow/.local/lib/python3.12/site-packages/airflow/models/taskinstance.py", line 3161, in _execute_task_with_callbacks
    result = self._execute_task(context, task_orig)
             ^^^^^^^^^^^^^^^^^^^^^^^^^^^^^^^^^^^^^^
  File "/home/airflow/.local/lib/python3.12/site-packages/airflow/models/taskinstance.py", line 3185, in _execute_task
    return _execute_task(self, context, task_orig)
           ^^^^^^^^^^^^^^^^^^^^^^^^^^^^^^^^^^^^^^^
  File "/home/airflow/.local/lib/python3.12/site-packages/airflow/models/taskinstance.py", line 768, in _execute_task
    result = _execute_callable(context=context, **execute_callable_kwargs)
             ^^^^^^^^^^^^^^^^^^^^^^^^^^^^^^^^^^^^^^^^^^^^^^^^^^^^^^^^^^^^^
  File "/home/airflow/.local/lib/python3.12/site-packages/airflow/models/taskinstance.py", line 734, in _execute_callable
    return ExecutionCallableRunner(
           ^^^^^^^^^^^^^^^^^^^^^^^^
  File "/home/airflow/.local/lib/python3.12/site-packages/airflow/utils/operator_helpers.py", line 252, in run
    return self.func(*args, **kwargs)
           ^^^^^^^^^^^^^^^^^^^^^^^^^^
  File "/home/airflow/.local/lib/python3.12/site-packages/airflow/models/baseoperator.py", line 424, in wrapper
    return func(self, *args, **kwargs)
           ^^^^^^^^^^^^^^^^^^^^^^^^^^^
  File "/home/airflow/.local/lib/python3.12/site-packages/airflow/operators/bash.py", line 276, in execute
    raise AirflowException(
airflow.exceptions.AirflowException: Bash command failed. The command returned a non-zero exit code 1.
[2025-04-14T17:26:07.910+0000] {local_task_job_runner.py:266} INFO - Task exited with return code 1
[2025-04-14T17:26:07.933+0000] {taskinstance.py:3901} INFO - 0 downstream tasks scheduled from follow-on schedule check
[2025-04-14T17:26:07.935+0000] {local_task_job_runner.py:245} INFO - ::endgroup::
