[2025-04-14T16:57:57.539+0000] {local_task_job_runner.py:123} INFO - ::group::Pre task execution logs
[2025-04-14T16:57:57.567+0000] {taskinstance.py:2614} INFO - Dependencies all met for dep_context=non-requeueable deps ti=<TaskInstance: dbt_airflow.run_dbt_core manual__2025-04-14T15:18:53.940263+00:00 [queued]>
[2025-04-14T16:57:57.581+0000] {taskinstance.py:2614} INFO - Dependencies all met for dep_context=requeueable deps ti=<TaskInstance: dbt_airflow.run_dbt_core manual__2025-04-14T15:18:53.940263+00:00 [queued]>
[2025-04-14T16:57:57.582+0000] {taskinstance.py:2867} INFO - Starting attempt 9 of 10
[2025-04-14T16:57:57.597+0000] {taskinstance.py:2890} INFO - Executing <Task(BashOperator): run_dbt_core> on 2025-04-14 15:18:53.940263+00:00
[2025-04-14T16:57:57.605+0000] {logging_mixin.py:190} WARNING - /home/***/.local/lib/python3.12/site-packages/***/task/task_runner/standard_task_runner.py:70 DeprecationWarning: This process (pid=12531) is multi-threaded, use of fork() may lead to deadlocks in the child.
[2025-04-14T16:57:57.606+0000] {standard_task_runner.py:72} INFO - Started process 12532 to run task
[2025-04-14T16:57:57.605+0000] {standard_task_runner.py:104} INFO - Running: ['***', 'tasks', 'run', 'dbt_***', 'run_dbt_core', 'manual__2025-04-14T15:18:53.940263+00:00', '--job-id', '502', '--raw', '--subdir', 'DAGS_FOLDER/run_dbt_model.py', '--cfg-path', '/tmp/tmpno7fz6o0']
[2025-04-14T16:57:57.608+0000] {standard_task_runner.py:105} INFO - Job 502: Subtask run_dbt_core
[2025-04-14T16:57:57.660+0000] {task_command.py:467} INFO - Running <TaskInstance: dbt_airflow.run_dbt_core manual__2025-04-14T15:18:53.940263+00:00 [running]> on host b7be566335ce
[2025-04-14T16:57:57.781+0000] {taskinstance.py:3134} INFO - Exporting env vars: AIRFLOW_CTX_DAG_OWNER='***' AIRFLOW_CTX_DAG_ID='dbt_***' AIRFLOW_CTX_TASK_ID='run_dbt_core' AIRFLOW_CTX_EXECUTION_DATE='2025-04-14T15:18:53.940263+00:00' AIRFLOW_CTX_TRY_NUMBER='9' AIRFLOW_CTX_DAG_RUN_ID='manual__2025-04-14T15:18:53.940263+00:00'
[2025-04-14T16:57:57.782+0000] {taskinstance.py:732} INFO - ::endgroup::
[2025-04-14T16:57:57.812+0000] {subprocess.py:78} INFO - Tmp dir root location: /tmp
[2025-04-14T16:57:57.813+0000] {subprocess.py:88} INFO - Running command: ['/usr/bin/bash', '-c', 'cd /opt/***/dbt && dbt run --models core_flights']
[2025-04-14T16:57:57.826+0000] {subprocess.py:99} INFO - Output:
[2025-04-14T16:58:02.978+0000] {subprocess.py:106} INFO - [0m16:58:02  Running with dbt=1.7.9
[2025-04-14T16:58:04.916+0000] {subprocess.py:106} INFO - [0m16:58:04  Registered adapter: bigquery=1.7.9
[2025-04-14T16:58:06.360+0000] {subprocess.py:106} INFO - [0m16:58:06  Found 2 models, 1 seed, 1 source, 0 exposures, 0 metrics, 570 macros, 0 groups, 0 semantic models
[2025-04-14T16:58:06.364+0000] {subprocess.py:106} INFO - [0m16:58:06
[2025-04-14T16:58:07.247+0000] {subprocess.py:106} INFO - [0m16:58:07  Concurrency: 1 threads (target='dev')
[2025-04-14T16:58:07.249+0000] {subprocess.py:106} INFO - [0m16:58:07
[2025-04-14T16:58:07.262+0000] {subprocess.py:106} INFO - [0m16:58:07  1 of 1 START sql table model db_project_dataset.core_flights ................... [RUN]
[2025-04-14T16:58:10.039+0000] {subprocess.py:106} INFO - [0m16:58:10  BigQuery adapter: https://console.cloud.google.com/bigquery?project=db-project-456518&j=bq:europe-central2:61893623-db26-47ee-ad32-17d016731f51&page=queryresults
[2025-04-14T16:58:10.055+0000] {subprocess.py:106} INFO - [0m16:58:10  1 of 1 ERROR creating sql table model db_project_dataset.core_flights .......... [[31mERROR[0m in 2.79s]
[2025-04-14T16:58:10.063+0000] {subprocess.py:106} INFO - [0m16:58:10
[2025-04-14T16:58:10.064+0000] {subprocess.py:106} INFO - [0m16:58:10  Finished running 1 table model in 0 hours 0 minutes and 3.70 seconds (3.70s).
[2025-04-14T16:58:10.097+0000] {subprocess.py:106} INFO - [0m16:58:10
[2025-04-14T16:58:10.099+0000] {subprocess.py:106} INFO - [0m16:58:10  [31mCompleted with 1 error and 0 warnings:[0m
[2025-04-14T16:58:10.100+0000] {subprocess.py:106} INFO - [0m16:58:10
[2025-04-14T16:58:10.101+0000] {subprocess.py:106} INFO - [0m16:58:10    Database Error in model core_flights (models/core/core_flights.sql)
[2025-04-14T16:58:10.102+0000] {subprocess.py:106} INFO -   Invalid timestamp: '1988-11-21 19:48'
[2025-04-14T16:58:10.103+0000] {subprocess.py:106} INFO -   compiled Code at target/run/flights_project/models/core/core_flights.sql
[2025-04-14T16:58:10.103+0000] {subprocess.py:106} INFO - [0m16:58:10
[2025-04-14T16:58:10.104+0000] {subprocess.py:106} INFO - [0m16:58:10  Done. PASS=0 WARN=0 ERROR=1 SKIP=0 TOTAL=1
[2025-04-14T16:58:11.134+0000] {subprocess.py:110} INFO - Command exited with return code 1
[2025-04-14T16:58:11.145+0000] {taskinstance.py:3313} ERROR - Task failed with exception
Traceback (most recent call last):
  File "/home/airflow/.local/lib/python3.12/site-packages/airflow/models/taskinstance.py", line 768, in _execute_task
    result = _execute_callable(context=context, **execute_callable_kwargs)
             ^^^^^^^^^^^^^^^^^^^^^^^^^^^^^^^^^^^^^^^^^^^^^^^^^^^^^^^^^^^^^
  File "/home/airflow/.local/lib/python3.12/site-packages/airflow/models/taskinstance.py", line 734, in _execute_callable
    return ExecutionCallableRunner(
           ^^^^^^^^^^^^^^^^^^^^^^^^
  File "/home/airflow/.local/lib/python3.12/site-packages/airflow/utils/operator_helpers.py", line 252, in run
    return self.func(*args, **kwargs)
           ^^^^^^^^^^^^^^^^^^^^^^^^^^
  File "/home/airflow/.local/lib/python3.12/site-packages/airflow/models/baseoperator.py", line 424, in wrapper
    return func(self, *args, **kwargs)
           ^^^^^^^^^^^^^^^^^^^^^^^^^^^
  File "/home/airflow/.local/lib/python3.12/site-packages/airflow/operators/bash.py", line 276, in execute
    raise AirflowException(
airflow.exceptions.AirflowException: Bash command failed. The command returned a non-zero exit code 1.
[2025-04-14T16:58:11.153+0000] {taskinstance.py:1226} INFO - Marking task as UP_FOR_RETRY. dag_id=dbt_***, task_id=run_dbt_core, run_id=manual__2025-04-14T15:18:53.940263+00:00, execution_date=20250414T151853, start_date=20250414T165757, end_date=20250414T165811
[2025-04-14T16:58:11.185+0000] {taskinstance.py:341} INFO - ::group::Post task execution logs
[2025-04-14T16:58:11.186+0000] {standard_task_runner.py:124} ERROR - Failed to execute job 502 for task run_dbt_core (Bash command failed. The command returned a non-zero exit code 1.; 12532)
Traceback (most recent call last):
  File "/home/airflow/.local/lib/python3.12/site-packages/airflow/task/task_runner/standard_task_runner.py", line 117, in _start_by_fork
    ret = args.func(args, dag=self.dag)
          ^^^^^^^^^^^^^^^^^^^^^^^^^^^^^
  File "/home/airflow/.local/lib/python3.12/site-packages/airflow/cli/cli_config.py", line 49, in command
    return func(*args, **kwargs)
           ^^^^^^^^^^^^^^^^^^^^^
  File "/home/airflow/.local/lib/python3.12/site-packages/airflow/utils/cli.py", line 116, in wrapper
    return f(*args, **kwargs)
           ^^^^^^^^^^^^^^^^^^
  File "/home/airflow/.local/lib/python3.12/site-packages/airflow/cli/commands/task_command.py", line 483, in task_run
    task_return_code = _run_task_by_selected_method(args, _dag, ti)
                       ^^^^^^^^^^^^^^^^^^^^^^^^^^^^^^^^^^^^^^^^^^^^
  File "/home/airflow/.local/lib/python3.12/site-packages/airflow/cli/commands/task_command.py", line 256, in _run_task_by_selected_method
    return _run_raw_task(args, ti)
           ^^^^^^^^^^^^^^^^^^^^^^^
  File "/home/airflow/.local/lib/python3.12/site-packages/airflow/cli/commands/task_command.py", line 341, in _run_raw_task
    return ti._run_raw_task(
           ^^^^^^^^^^^^^^^^^
  File "/home/airflow/.local/lib/python3.12/site-packages/airflow/utils/session.py", line 97, in wrapper
    return func(*args, session=session, **kwargs)
           ^^^^^^^^^^^^^^^^^^^^^^^^^^^^^^^^^^^^^^
  File "/home/airflow/.local/lib/python3.12/site-packages/airflow/models/taskinstance.py", line 3006, in _run_raw_task
    return _run_raw_task(
           ^^^^^^^^^^^^^^
  File "/home/airflow/.local/lib/python3.12/site-packages/airflow/models/taskinstance.py", line 274, in _run_raw_task
    TaskInstance._execute_task_with_callbacks(
  File "/home/airflow/.local/lib/python3.12/site-packages/airflow/models/taskinstance.py", line 3161, in _execute_task_with_callbacks
    result = self._execute_task(context, task_orig)
             ^^^^^^^^^^^^^^^^^^^^^^^^^^^^^^^^^^^^^^
  File "/home/airflow/.local/lib/python3.12/site-packages/airflow/models/taskinstance.py", line 3185, in _execute_task
    return _execute_task(self, context, task_orig)
           ^^^^^^^^^^^^^^^^^^^^^^^^^^^^^^^^^^^^^^^
  File "/home/airflow/.local/lib/python3.12/site-packages/airflow/models/taskinstance.py", line 768, in _execute_task
    result = _execute_callable(context=context, **execute_callable_kwargs)
             ^^^^^^^^^^^^^^^^^^^^^^^^^^^^^^^^^^^^^^^^^^^^^^^^^^^^^^^^^^^^^
  File "/home/airflow/.local/lib/python3.12/site-packages/airflow/models/taskinstance.py", line 734, in _execute_callable
    return ExecutionCallableRunner(
           ^^^^^^^^^^^^^^^^^^^^^^^^
  File "/home/airflow/.local/lib/python3.12/site-packages/airflow/utils/operator_helpers.py", line 252, in run
    return self.func(*args, **kwargs)
           ^^^^^^^^^^^^^^^^^^^^^^^^^^
  File "/home/airflow/.local/lib/python3.12/site-packages/airflow/models/baseoperator.py", line 424, in wrapper
    return func(self, *args, **kwargs)
           ^^^^^^^^^^^^^^^^^^^^^^^^^^^
  File "/home/airflow/.local/lib/python3.12/site-packages/airflow/operators/bash.py", line 276, in execute
    raise AirflowException(
airflow.exceptions.AirflowException: Bash command failed. The command returned a non-zero exit code 1.
[2025-04-14T16:58:11.195+0000] {local_task_job_runner.py:266} INFO - Task exited with return code 1
[2025-04-14T16:58:11.220+0000] {taskinstance.py:3901} INFO - 0 downstream tasks scheduled from follow-on schedule check
[2025-04-14T16:58:11.223+0000] {local_task_job_runner.py:245} INFO - ::endgroup::
