[2025-04-18T16:45:12.575+0000] {local_task_job_runner.py:123} INFO - ::group::Pre task execution logs
[2025-04-18T16:45:12.600+0000] {taskinstance.py:2614} INFO - Dependencies all met for dep_context=non-requeueable deps ti=<TaskInstance: kaggle_seeds_to_gcs.download_seeds_from_kaggle scheduled__2025-01-01T00:00:00+00:00 [queued]>
[2025-04-18T16:45:12.615+0000] {taskinstance.py:2614} INFO - Dependencies all met for dep_context=requeueable deps ti=<TaskInstance: kaggle_seeds_to_gcs.download_seeds_from_kaggle scheduled__2025-01-01T00:00:00+00:00 [queued]>
[2025-04-18T16:45:12.616+0000] {taskinstance.py:2867} INFO - Starting attempt 2 of 3
[2025-04-18T16:45:12.635+0000] {taskinstance.py:2890} INFO - Executing <Task(PythonOperator): download_seeds_from_kaggle> on 2025-01-01 00:00:00+00:00
[2025-04-18T16:45:12.646+0000] {standard_task_runner.py:104} INFO - Running: ['***', 'tasks', 'run', 'kaggle_seeds_to_gcs', 'download_seeds_from_kaggle', 'scheduled__2025-01-01T00:00:00+00:00', '--job-id', '587', '--raw', '--subdir', 'DAGS_FOLDER/kaggle_seeds_to_gcs.py', '--cfg-path', '/tmp/tmpqqxrin2x']
[2025-04-18T16:45:12.650+0000] {standard_task_runner.py:105} INFO - Job 587: Subtask download_seeds_from_kaggle
[2025-04-18T16:45:12.653+0000] {logging_mixin.py:190} WARNING - /home/***/.local/lib/python3.12/site-packages/***/task/task_runner/standard_task_runner.py:70 DeprecationWarning: This process (pid=17997) is multi-threaded, use of fork() may lead to deadlocks in the child.
[2025-04-18T16:45:12.655+0000] {standard_task_runner.py:72} INFO - Started process 18000 to run task
[2025-04-18T16:45:12.707+0000] {task_command.py:467} INFO - Running <TaskInstance: kaggle_seeds_to_gcs.download_seeds_from_kaggle scheduled__2025-01-01T00:00:00+00:00 [running]> on host f21ba0bbe878
[2025-04-18T16:45:13.069+0000] {taskinstance.py:3134} INFO - Exporting env vars: AIRFLOW_CTX_DAG_OWNER='***' AIRFLOW_CTX_DAG_ID='kaggle_seeds_to_gcs' AIRFLOW_CTX_TASK_ID='download_seeds_from_kaggle' AIRFLOW_CTX_EXECUTION_DATE='2025-01-01T00:00:00+00:00' AIRFLOW_CTX_TRY_NUMBER='2' AIRFLOW_CTX_DAG_RUN_ID='scheduled__2025-01-01T00:00:00+00:00'
[2025-04-18T16:45:13.071+0000] {taskinstance.py:732} INFO - ::endgroup::
[2025-04-18T16:45:13.093+0000] {logging_mixin.py:190} INFO - Dataset URL: https://www.kaggle.com/datasets/viggo123/data-fight-usa-dataset
[2025-04-18T16:45:13.890+0000] {logging_mixin.py:190} INFO - Downloading carriers.csv to /tmp/kaggle_downloads
[2025-04-18T16:45:13.895+0000] {logging_mixin.py:190} WARNING -   0%|          | 0.00/42.7k [00:00<?, ?B/s]
[2025-04-18T16:45:13.895+0000] {logging_mixin.py:190} WARNING - 100%|##########| 42.7k/42.7k [00:00<00:00, 172MB/s]
[2025-04-18T16:45:13.897+0000] {logging_mixin.py:190} INFO - Dataset URL: https://www.kaggle.com/datasets/viggo123/data-fight-usa-dataset
[2025-04-18T16:45:14.994+0000] {logging_mixin.py:190} INFO - Downloading airports.csv to /tmp/kaggle_downloads
[2025-04-18T16:45:14.995+0000] {logging_mixin.py:190} WARNING -   0%|          | 0.00/239k [00:00<?, ?B/s]
[2025-04-18T16:45:14.997+0000] {logging_mixin.py:190} WARNING - 100%|##########| 239k/239k [00:00<00:00, 234MB/s]
[2025-04-18T16:45:14.999+0000] {logging_mixin.py:190} INFO - Dataset URL: https://www.kaggle.com/datasets/viggo123/data-fight-usa-dataset
[2025-04-18T16:45:15.303+0000] {taskinstance.py:3313} ERROR - Task failed with exception
Traceback (most recent call last):
  File "/home/airflow/.local/lib/python3.12/site-packages/airflow/models/taskinstance.py", line 768, in _execute_task
    result = _execute_callable(context=context, **execute_callable_kwargs)
             ^^^^^^^^^^^^^^^^^^^^^^^^^^^^^^^^^^^^^^^^^^^^^^^^^^^^^^^^^^^^^
  File "/home/airflow/.local/lib/python3.12/site-packages/airflow/models/taskinstance.py", line 734, in _execute_callable
    return ExecutionCallableRunner(
           ^^^^^^^^^^^^^^^^^^^^^^^^
  File "/home/airflow/.local/lib/python3.12/site-packages/airflow/utils/operator_helpers.py", line 252, in run
    return self.func(*args, **kwargs)
           ^^^^^^^^^^^^^^^^^^^^^^^^^^
  File "/home/airflow/.local/lib/python3.12/site-packages/airflow/models/baseoperator.py", line 424, in wrapper
    return func(self, *args, **kwargs)
           ^^^^^^^^^^^^^^^^^^^^^^^^^^^
  File "/home/airflow/.local/lib/python3.12/site-packages/airflow/operators/python.py", line 238, in execute
    return_value = self.execute_callable()
                   ^^^^^^^^^^^^^^^^^^^^^^^
  File "/home/airflow/.local/lib/python3.12/site-packages/airflow/operators/python.py", line 256, in execute_callable
    return runner.run(*self.op_args, **self.op_kwargs)
           ^^^^^^^^^^^^^^^^^^^^^^^^^^^^^^^^^^^^^^^^^^^
  File "/home/airflow/.local/lib/python3.12/site-packages/airflow/utils/operator_helpers.py", line 252, in run
    return self.func(*args, **kwargs)
           ^^^^^^^^^^^^^^^^^^^^^^^^^^
  File "/opt/airflow/dags/kaggle_seeds_to_gcs.py", line 29, in download_seeds_from_kaggle
    api.dataset_download_file(
  File "/home/airflow/.local/lib/python3.12/site-packages/kaggle/api/kaggle_api_extended.py", line 1610, in dataset_download_file
    response = kaggle.datasets.dataset_api_client.download_dataset(request)
               ^^^^^^^^^^^^^^^^^^^^^^^^^^^^^^^^^^^^^^^^^^^^^^^^^^^^^^^^^^^^
  File "/home/airflow/.local/lib/python3.12/site-packages/kagglesdk/datasets/services/dataset_api_service.py", line 80, in download_dataset
    return self._client.call("datasets.DatasetApiService", "ApiDownloadDataset", request, HttpRedirect)
           ^^^^^^^^^^^^^^^^^^^^^^^^^^^^^^^^^^^^^^^^^^^^^^^^^^^^^^^^^^^^^^^^^^^^^^^^^^^^^^^^^^^^^^^^^^^^
  File "/home/airflow/.local/lib/python3.12/site-packages/kagglesdk/kaggle_http_client.py", line 104, in call
    response = self._prepare_response(response_type, http_response)
               ^^^^^^^^^^^^^^^^^^^^^^^^^^^^^^^^^^^^^^^^^^^^^^^^^^^^
  File "/home/airflow/.local/lib/python3.12/site-packages/kagglesdk/kaggle_http_client.py", line 163, in _prepare_response
    http_response.raise_for_status()
  File "/home/airflow/.local/lib/python3.12/site-packages/requests/models.py", line 1024, in raise_for_status
    raise HTTPError(http_error_msg, response=self)
requests.exceptions.HTTPError: 404 Client Error: Not Found for url: https://www.kaggle.com/api/v1/datasets/download/viggo123/data-fight-usa-dataset/plane_data.csv?filename=plane_data.csv&raw=false
[2025-04-18T16:45:15.331+0000] {taskinstance.py:1226} INFO - Marking task as UP_FOR_RETRY. dag_id=kaggle_seeds_to_gcs, task_id=download_seeds_from_kaggle, run_id=scheduled__2025-01-01T00:00:00+00:00, execution_date=20250101T000000, start_date=20250418T164512, end_date=20250418T164515
[2025-04-18T16:45:15.379+0000] {taskinstance.py:341} INFO - ::group::Post task execution logs
[2025-04-18T16:45:15.380+0000] {standard_task_runner.py:124} ERROR - Failed to execute job 587 for task download_seeds_from_kaggle (404 Client Error: Not Found for url: https://www.kaggle.com/api/v1/datasets/download/viggo123/data-fight-usa-dataset/plane_data.csv?filename=plane_data.csv&raw=false; 18000)
Traceback (most recent call last):
  File "/home/airflow/.local/lib/python3.12/site-packages/airflow/task/task_runner/standard_task_runner.py", line 117, in _start_by_fork
    ret = args.func(args, dag=self.dag)
          ^^^^^^^^^^^^^^^^^^^^^^^^^^^^^
  File "/home/airflow/.local/lib/python3.12/site-packages/airflow/cli/cli_config.py", line 49, in command
    return func(*args, **kwargs)
           ^^^^^^^^^^^^^^^^^^^^^
  File "/home/airflow/.local/lib/python3.12/site-packages/airflow/utils/cli.py", line 116, in wrapper
    return f(*args, **kwargs)
           ^^^^^^^^^^^^^^^^^^
  File "/home/airflow/.local/lib/python3.12/site-packages/airflow/cli/commands/task_command.py", line 483, in task_run
    task_return_code = _run_task_by_selected_method(args, _dag, ti)
                       ^^^^^^^^^^^^^^^^^^^^^^^^^^^^^^^^^^^^^^^^^^^^
  File "/home/airflow/.local/lib/python3.12/site-packages/airflow/cli/commands/task_command.py", line 256, in _run_task_by_selected_method
    return _run_raw_task(args, ti)
           ^^^^^^^^^^^^^^^^^^^^^^^
  File "/home/airflow/.local/lib/python3.12/site-packages/airflow/cli/commands/task_command.py", line 341, in _run_raw_task
    return ti._run_raw_task(
           ^^^^^^^^^^^^^^^^^
  File "/home/airflow/.local/lib/python3.12/site-packages/airflow/utils/session.py", line 97, in wrapper
    return func(*args, session=session, **kwargs)
           ^^^^^^^^^^^^^^^^^^^^^^^^^^^^^^^^^^^^^^
  File "/home/airflow/.local/lib/python3.12/site-packages/airflow/models/taskinstance.py", line 3006, in _run_raw_task
    return _run_raw_task(
           ^^^^^^^^^^^^^^
  File "/home/airflow/.local/lib/python3.12/site-packages/airflow/models/taskinstance.py", line 274, in _run_raw_task
    TaskInstance._execute_task_with_callbacks(
  File "/home/airflow/.local/lib/python3.12/site-packages/airflow/models/taskinstance.py", line 3161, in _execute_task_with_callbacks
    result = self._execute_task(context, task_orig)
             ^^^^^^^^^^^^^^^^^^^^^^^^^^^^^^^^^^^^^^
  File "/home/airflow/.local/lib/python3.12/site-packages/airflow/models/taskinstance.py", line 3185, in _execute_task
    return _execute_task(self, context, task_orig)
           ^^^^^^^^^^^^^^^^^^^^^^^^^^^^^^^^^^^^^^^
  File "/home/airflow/.local/lib/python3.12/site-packages/airflow/models/taskinstance.py", line 768, in _execute_task
    result = _execute_callable(context=context, **execute_callable_kwargs)
             ^^^^^^^^^^^^^^^^^^^^^^^^^^^^^^^^^^^^^^^^^^^^^^^^^^^^^^^^^^^^^
  File "/home/airflow/.local/lib/python3.12/site-packages/airflow/models/taskinstance.py", line 734, in _execute_callable
    return ExecutionCallableRunner(
           ^^^^^^^^^^^^^^^^^^^^^^^^
  File "/home/airflow/.local/lib/python3.12/site-packages/airflow/utils/operator_helpers.py", line 252, in run
    return self.func(*args, **kwargs)
           ^^^^^^^^^^^^^^^^^^^^^^^^^^
  File "/home/airflow/.local/lib/python3.12/site-packages/airflow/models/baseoperator.py", line 424, in wrapper
    return func(self, *args, **kwargs)
           ^^^^^^^^^^^^^^^^^^^^^^^^^^^
  File "/home/airflow/.local/lib/python3.12/site-packages/airflow/operators/python.py", line 238, in execute
    return_value = self.execute_callable()
                   ^^^^^^^^^^^^^^^^^^^^^^^
  File "/home/airflow/.local/lib/python3.12/site-packages/airflow/operators/python.py", line 256, in execute_callable
    return runner.run(*self.op_args, **self.op_kwargs)
           ^^^^^^^^^^^^^^^^^^^^^^^^^^^^^^^^^^^^^^^^^^^
  File "/home/airflow/.local/lib/python3.12/site-packages/airflow/utils/operator_helpers.py", line 252, in run
    return self.func(*args, **kwargs)
           ^^^^^^^^^^^^^^^^^^^^^^^^^^
  File "/opt/airflow/dags/kaggle_seeds_to_gcs.py", line 29, in download_seeds_from_kaggle
    api.dataset_download_file(
  File "/home/airflow/.local/lib/python3.12/site-packages/kaggle/api/kaggle_api_extended.py", line 1610, in dataset_download_file
    response = kaggle.datasets.dataset_api_client.download_dataset(request)
               ^^^^^^^^^^^^^^^^^^^^^^^^^^^^^^^^^^^^^^^^^^^^^^^^^^^^^^^^^^^^
  File "/home/airflow/.local/lib/python3.12/site-packages/kagglesdk/datasets/services/dataset_api_service.py", line 80, in download_dataset
    return self._client.call("datasets.DatasetApiService", "ApiDownloadDataset", request, HttpRedirect)
           ^^^^^^^^^^^^^^^^^^^^^^^^^^^^^^^^^^^^^^^^^^^^^^^^^^^^^^^^^^^^^^^^^^^^^^^^^^^^^^^^^^^^^^^^^^^^
  File "/home/airflow/.local/lib/python3.12/site-packages/kagglesdk/kaggle_http_client.py", line 104, in call
    response = self._prepare_response(response_type, http_response)
               ^^^^^^^^^^^^^^^^^^^^^^^^^^^^^^^^^^^^^^^^^^^^^^^^^^^^
  File "/home/airflow/.local/lib/python3.12/site-packages/kagglesdk/kaggle_http_client.py", line 163, in _prepare_response
    http_response.raise_for_status()
  File "/home/airflow/.local/lib/python3.12/site-packages/requests/models.py", line 1024, in raise_for_status
    raise HTTPError(http_error_msg, response=self)
requests.exceptions.HTTPError: 404 Client Error: Not Found for url: https://www.kaggle.com/api/v1/datasets/download/viggo123/data-fight-usa-dataset/plane_data.csv?filename=plane_data.csv&raw=false
[2025-04-18T16:45:15.403+0000] {local_task_job_runner.py:266} INFO - Task exited with return code 1
[2025-04-18T16:45:15.434+0000] {taskinstance.py:3901} INFO - 0 downstream tasks scheduled from follow-on schedule check
[2025-04-18T16:45:15.436+0000] {local_task_job_runner.py:245} INFO - ::endgroup::
