[2025-04-13T19:39:09.642+0000] {local_task_job_runner.py:123} INFO - ::group::Pre task execution logs
[2025-04-13T19:39:09.673+0000] {taskinstance.py:2614} INFO - Dependencies all met for dep_context=non-requeueable deps ti=<TaskInstance: gcs_dlt_data_pipeline.upload_file scheduled__1987-01-01T00:00:00+00:00 [queued]>
[2025-04-13T19:39:09.689+0000] {taskinstance.py:2614} INFO - Dependencies all met for dep_context=requeueable deps ti=<TaskInstance: gcs_dlt_data_pipeline.upload_file scheduled__1987-01-01T00:00:00+00:00 [queued]>
[2025-04-13T19:39:09.690+0000] {taskinstance.py:2867} INFO - Starting attempt 1 of 2
[2025-04-13T19:39:09.709+0000] {taskinstance.py:2890} INFO - Executing <Task(PythonOperator): upload_file> on 1987-01-01 00:00:00+00:00
[2025-04-13T19:39:09.726+0000] {logging_mixin.py:190} WARNING - /home/***/.local/lib/python3.12/site-packages/***/task/task_runner/standard_task_runner.py:70 DeprecationWarning: This process (pid=1466) is multi-threaded, use of fork() may lead to deadlocks in the child.
[2025-04-13T19:39:09.728+0000] {standard_task_runner.py:72} INFO - Started process 1468 to run task
[2025-04-13T19:39:09.726+0000] {standard_task_runner.py:104} INFO - Running: ['***', 'tasks', 'run', 'gcs_dlt_data_pipeline', 'upload_file', 'scheduled__1987-01-01T00:00:00+00:00', '--job-id', '166', '--raw', '--subdir', 'DAGS_FOLDER/first_stage/first_stage.py', '--cfg-path', '/tmp/tmpah9fy25f']
[2025-04-13T19:39:09.729+0000] {standard_task_runner.py:105} INFO - Job 166: Subtask upload_file
[2025-04-13T19:39:09.806+0000] {task_command.py:467} INFO - Running <TaskInstance: gcs_dlt_data_pipeline.upload_file scheduled__1987-01-01T00:00:00+00:00 [running]> on host 0728476a73c7
[2025-04-13T19:39:09.938+0000] {taskinstance.py:3134} INFO - Exporting env vars: AIRFLOW_CTX_DAG_OWNER='***' AIRFLOW_CTX_DAG_ID='gcs_dlt_data_pipeline' AIRFLOW_CTX_TASK_ID='upload_file' AIRFLOW_CTX_EXECUTION_DATE='1987-01-01T00:00:00+00:00' AIRFLOW_CTX_TRY_NUMBER='1' AIRFLOW_CTX_DAG_RUN_ID='scheduled__1987-01-01T00:00:00+00:00'
[2025-04-13T19:39:09.940+0000] {taskinstance.py:732} INFO - ::endgroup::
[2025-04-13T19:40:10.382+0000] {taskinstance.py:3313} ERROR - Task failed with exception
Traceback (most recent call last):
  File "/home/airflow/.local/lib/python3.12/site-packages/urllib3/connectionpool.py", line 716, in urlopen
    httplib_response = self._make_request(
                       ^^^^^^^^^^^^^^^^^^^
  File "/home/airflow/.local/lib/python3.12/site-packages/urllib3/connectionpool.py", line 416, in _make_request
    conn.request(method, url, **httplib_request_kw)
  File "/home/airflow/.local/lib/python3.12/site-packages/urllib3/connection.py", line 244, in request
    super(HTTPConnection, self).request(method, url, body=body, headers=headers)
  File "/usr/local/lib/python3.12/http/client.py", line 1338, in request
    self._send_request(method, url, body, headers, encode_chunked)
  File "/usr/local/lib/python3.12/http/client.py", line 1384, in _send_request
    self.endheaders(body, encode_chunked=encode_chunked)
  File "/usr/local/lib/python3.12/http/client.py", line 1333, in endheaders
    self._send_output(message_body, encode_chunked=encode_chunked)
  File "/usr/local/lib/python3.12/http/client.py", line 1132, in _send_output
    self.send(chunk)
  File "/usr/local/lib/python3.12/http/client.py", line 1057, in send
    self.sock.sendall(data)
  File "/usr/local/lib/python3.12/ssl.py", line 1210, in sendall
    v = self.send(byte_view[count:])
        ^^^^^^^^^^^^^^^^^^^^^^^^^^^^
  File "/usr/local/lib/python3.12/ssl.py", line 1179, in send
    return self._sslobj.write(data)
           ^^^^^^^^^^^^^^^^^^^^^^^^
TimeoutError: The write operation timed out

During handling of the above exception, another exception occurred:

Traceback (most recent call last):
  File "/home/airflow/.local/lib/python3.12/site-packages/requests/adapters.py", line 667, in send
    resp = conn.urlopen(
           ^^^^^^^^^^^^^
  File "/home/airflow/.local/lib/python3.12/site-packages/urllib3/connectionpool.py", line 802, in urlopen
    retries = retries.increment(
              ^^^^^^^^^^^^^^^^^^
  File "/home/airflow/.local/lib/python3.12/site-packages/urllib3/util/retry.py", line 552, in increment
    raise six.reraise(type(error), error, _stacktrace)
          ^^^^^^^^^^^^^^^^^^^^^^^^^^^^^^^^^^^^^^^^^^^^
  File "/home/airflow/.local/lib/python3.12/site-packages/urllib3/packages/six.py", line 769, in reraise
    raise value.with_traceback(tb)
  File "/home/airflow/.local/lib/python3.12/site-packages/urllib3/connectionpool.py", line 716, in urlopen
    httplib_response = self._make_request(
                       ^^^^^^^^^^^^^^^^^^^
  File "/home/airflow/.local/lib/python3.12/site-packages/urllib3/connectionpool.py", line 416, in _make_request
    conn.request(method, url, **httplib_request_kw)
  File "/home/airflow/.local/lib/python3.12/site-packages/urllib3/connection.py", line 244, in request
    super(HTTPConnection, self).request(method, url, body=body, headers=headers)
  File "/usr/local/lib/python3.12/http/client.py", line 1338, in request
    self._send_request(method, url, body, headers, encode_chunked)
  File "/usr/local/lib/python3.12/http/client.py", line 1384, in _send_request
    self.endheaders(body, encode_chunked=encode_chunked)
  File "/usr/local/lib/python3.12/http/client.py", line 1333, in endheaders
    self._send_output(message_body, encode_chunked=encode_chunked)
  File "/usr/local/lib/python3.12/http/client.py", line 1132, in _send_output
    self.send(chunk)
  File "/usr/local/lib/python3.12/http/client.py", line 1057, in send
    self.sock.sendall(data)
  File "/usr/local/lib/python3.12/ssl.py", line 1210, in sendall
    v = self.send(byte_view[count:])
        ^^^^^^^^^^^^^^^^^^^^^^^^^^^^
  File "/usr/local/lib/python3.12/ssl.py", line 1179, in send
    return self._sslobj.write(data)
           ^^^^^^^^^^^^^^^^^^^^^^^^
urllib3.exceptions.ProtocolError: ('Connection aborted.', TimeoutError('The write operation timed out'))

During handling of the above exception, another exception occurred:

Traceback (most recent call last):
  File "/home/airflow/.local/lib/python3.12/site-packages/airflow/models/taskinstance.py", line 768, in _execute_task
    result = _execute_callable(context=context, **execute_callable_kwargs)
             ^^^^^^^^^^^^^^^^^^^^^^^^^^^^^^^^^^^^^^^^^^^^^^^^^^^^^^^^^^^^^
  File "/home/airflow/.local/lib/python3.12/site-packages/airflow/models/taskinstance.py", line 734, in _execute_callable
    return ExecutionCallableRunner(
           ^^^^^^^^^^^^^^^^^^^^^^^^
  File "/home/airflow/.local/lib/python3.12/site-packages/airflow/utils/operator_helpers.py", line 252, in run
    return self.func(*args, **kwargs)
           ^^^^^^^^^^^^^^^^^^^^^^^^^^
  File "/home/airflow/.local/lib/python3.12/site-packages/airflow/models/baseoperator.py", line 424, in wrapper
    return func(self, *args, **kwargs)
           ^^^^^^^^^^^^^^^^^^^^^^^^^^^
  File "/home/airflow/.local/lib/python3.12/site-packages/airflow/operators/python.py", line 238, in execute
    return_value = self.execute_callable()
                   ^^^^^^^^^^^^^^^^^^^^^^^
  File "/home/airflow/.local/lib/python3.12/site-packages/airflow/operators/python.py", line 256, in execute_callable
    return runner.run(*self.op_args, **self.op_kwargs)
           ^^^^^^^^^^^^^^^^^^^^^^^^^^^^^^^^^^^^^^^^^^^
  File "/home/airflow/.local/lib/python3.12/site-packages/airflow/utils/operator_helpers.py", line 252, in run
    return self.func(*args, **kwargs)
           ^^^^^^^^^^^^^^^^^^^^^^^^^^
  File "/opt/airflow/dags/first_stage/first_stage.py", line 64, in gcs_destination
    upload_gcs_file(GCS_BUCKET_NAME, file_path, destination_blob_name)
  File "/opt/airflow/dags/first_stage/first_stage.py", line 28, in upload_gcs_file
    blob.upload_from_filename(source_file_name)
  File "/usr/local/lib/python3.12/contextlib.py", line 81, in inner
    return func(*args, **kwds)
           ^^^^^^^^^^^^^^^^^^^
  File "/home/airflow/.local/lib/python3.12/site-packages/google/cloud/storage/blob.py", line 3006, in upload_from_filename
    self._handle_filename_and_upload(
  File "/home/airflow/.local/lib/python3.12/site-packages/google/cloud/storage/blob.py", line 2884, in _handle_filename_and_upload
    self._prep_and_do_upload(
  File "/home/airflow/.local/lib/python3.12/site-packages/google/cloud/storage/blob.py", line 2700, in _prep_and_do_upload
    created_json = self._do_upload(
                   ^^^^^^^^^^^^^^^^
  File "/home/airflow/.local/lib/python3.12/site-packages/google/cloud/storage/blob.py", line 2523, in _do_upload
    response = self._do_resumable_upload(
               ^^^^^^^^^^^^^^^^^^^^^^^^^^
  File "/home/airflow/.local/lib/python3.12/site-packages/google/cloud/storage/blob.py", line 2359, in _do_resumable_upload
    response = upload.transmit_next_chunk(transport, timeout=timeout)
               ^^^^^^^^^^^^^^^^^^^^^^^^^^^^^^^^^^^^^^^^^^^^^^^^^^^^^^
  File "/home/airflow/.local/lib/python3.12/site-packages/google/resumable_media/requests/upload.py", line 515, in transmit_next_chunk
    return _request_helpers.wait_and_retry(
           ^^^^^^^^^^^^^^^^^^^^^^^^^^^^^^^^
  File "/home/airflow/.local/lib/python3.12/site-packages/google/resumable_media/requests/_request_helpers.py", line 178, in wait_and_retry
    raise error
  File "/home/airflow/.local/lib/python3.12/site-packages/google/resumable_media/requests/_request_helpers.py", line 155, in wait_and_retry
    response = func()
               ^^^^^^
  File "/home/airflow/.local/lib/python3.12/site-packages/google/resumable_media/requests/upload.py", line 507, in retriable_request
    result = transport.request(
             ^^^^^^^^^^^^^^^^^^
  File "/home/airflow/.local/lib/python3.12/site-packages/google/auth/transport/requests.py", line 537, in request
    response = super(AuthorizedSession, self).request(
               ^^^^^^^^^^^^^^^^^^^^^^^^^^^^^^^^^^^^^^^
  File "/home/airflow/.local/lib/python3.12/site-packages/requests/sessions.py", line 589, in request
    resp = self.send(prep, **send_kwargs)
           ^^^^^^^^^^^^^^^^^^^^^^^^^^^^^^
  File "/home/airflow/.local/lib/python3.12/site-packages/requests/sessions.py", line 703, in send
    r = adapter.send(request, **kwargs)
        ^^^^^^^^^^^^^^^^^^^^^^^^^^^^^^^
  File "/home/airflow/.local/lib/python3.12/site-packages/requests/adapters.py", line 682, in send
    raise ConnectionError(err, request=request)
requests.exceptions.ConnectionError: ('Connection aborted.', TimeoutError('The write operation timed out'))
[2025-04-13T19:40:10.483+0000] {taskinstance.py:1226} INFO - Marking task as UP_FOR_RETRY. dag_id=gcs_dlt_data_pipeline, task_id=upload_file, run_id=scheduled__1987-01-01T00:00:00+00:00, execution_date=19870101T000000, start_date=20250413T193909, end_date=20250413T194010
[2025-04-13T19:40:10.551+0000] {taskinstance.py:341} INFO - ::group::Post task execution logs
[2025-04-13T19:40:10.552+0000] {standard_task_runner.py:124} ERROR - Failed to execute job 166 for task upload_file (('Connection aborted.', TimeoutError('The write operation timed out')); 1468)
Traceback (most recent call last):
  File "/home/airflow/.local/lib/python3.12/site-packages/urllib3/connectionpool.py", line 716, in urlopen
    httplib_response = self._make_request(
                       ^^^^^^^^^^^^^^^^^^^
  File "/home/airflow/.local/lib/python3.12/site-packages/urllib3/connectionpool.py", line 416, in _make_request
    conn.request(method, url, **httplib_request_kw)
  File "/home/airflow/.local/lib/python3.12/site-packages/urllib3/connection.py", line 244, in request
    super(HTTPConnection, self).request(method, url, body=body, headers=headers)
  File "/usr/local/lib/python3.12/http/client.py", line 1338, in request
    self._send_request(method, url, body, headers, encode_chunked)
  File "/usr/local/lib/python3.12/http/client.py", line 1384, in _send_request
    self.endheaders(body, encode_chunked=encode_chunked)
  File "/usr/local/lib/python3.12/http/client.py", line 1333, in endheaders
    self._send_output(message_body, encode_chunked=encode_chunked)
  File "/usr/local/lib/python3.12/http/client.py", line 1132, in _send_output
    self.send(chunk)
  File "/usr/local/lib/python3.12/http/client.py", line 1057, in send
    self.sock.sendall(data)
  File "/usr/local/lib/python3.12/ssl.py", line 1210, in sendall
    v = self.send(byte_view[count:])
        ^^^^^^^^^^^^^^^^^^^^^^^^^^^^
  File "/usr/local/lib/python3.12/ssl.py", line 1179, in send
    return self._sslobj.write(data)
           ^^^^^^^^^^^^^^^^^^^^^^^^
TimeoutError: The write operation timed out

During handling of the above exception, another exception occurred:

Traceback (most recent call last):
  File "/home/airflow/.local/lib/python3.12/site-packages/requests/adapters.py", line 667, in send
    resp = conn.urlopen(
           ^^^^^^^^^^^^^
  File "/home/airflow/.local/lib/python3.12/site-packages/urllib3/connectionpool.py", line 802, in urlopen
    retries = retries.increment(
              ^^^^^^^^^^^^^^^^^^
  File "/home/airflow/.local/lib/python3.12/site-packages/urllib3/util/retry.py", line 552, in increment
    raise six.reraise(type(error), error, _stacktrace)
          ^^^^^^^^^^^^^^^^^^^^^^^^^^^^^^^^^^^^^^^^^^^^
  File "/home/airflow/.local/lib/python3.12/site-packages/urllib3/packages/six.py", line 769, in reraise
    raise value.with_traceback(tb)
  File "/home/airflow/.local/lib/python3.12/site-packages/urllib3/connectionpool.py", line 716, in urlopen
    httplib_response = self._make_request(
                       ^^^^^^^^^^^^^^^^^^^
  File "/home/airflow/.local/lib/python3.12/site-packages/urllib3/connectionpool.py", line 416, in _make_request
    conn.request(method, url, **httplib_request_kw)
  File "/home/airflow/.local/lib/python3.12/site-packages/urllib3/connection.py", line 244, in request
    super(HTTPConnection, self).request(method, url, body=body, headers=headers)
  File "/usr/local/lib/python3.12/http/client.py", line 1338, in request
    self._send_request(method, url, body, headers, encode_chunked)
  File "/usr/local/lib/python3.12/http/client.py", line 1384, in _send_request
    self.endheaders(body, encode_chunked=encode_chunked)
  File "/usr/local/lib/python3.12/http/client.py", line 1333, in endheaders
    self._send_output(message_body, encode_chunked=encode_chunked)
  File "/usr/local/lib/python3.12/http/client.py", line 1132, in _send_output
    self.send(chunk)
  File "/usr/local/lib/python3.12/http/client.py", line 1057, in send
    self.sock.sendall(data)
  File "/usr/local/lib/python3.12/ssl.py", line 1210, in sendall
    v = self.send(byte_view[count:])
        ^^^^^^^^^^^^^^^^^^^^^^^^^^^^
  File "/usr/local/lib/python3.12/ssl.py", line 1179, in send
    return self._sslobj.write(data)
           ^^^^^^^^^^^^^^^^^^^^^^^^
urllib3.exceptions.ProtocolError: ('Connection aborted.', TimeoutError('The write operation timed out'))

During handling of the above exception, another exception occurred:

Traceback (most recent call last):
  File "/home/airflow/.local/lib/python3.12/site-packages/airflow/task/task_runner/standard_task_runner.py", line 117, in _start_by_fork
    ret = args.func(args, dag=self.dag)
          ^^^^^^^^^^^^^^^^^^^^^^^^^^^^^
  File "/home/airflow/.local/lib/python3.12/site-packages/airflow/cli/cli_config.py", line 49, in command
    return func(*args, **kwargs)
           ^^^^^^^^^^^^^^^^^^^^^
  File "/home/airflow/.local/lib/python3.12/site-packages/airflow/utils/cli.py", line 116, in wrapper
    return f(*args, **kwargs)
           ^^^^^^^^^^^^^^^^^^
  File "/home/airflow/.local/lib/python3.12/site-packages/airflow/cli/commands/task_command.py", line 483, in task_run
    task_return_code = _run_task_by_selected_method(args, _dag, ti)
                       ^^^^^^^^^^^^^^^^^^^^^^^^^^^^^^^^^^^^^^^^^^^^
  File "/home/airflow/.local/lib/python3.12/site-packages/airflow/cli/commands/task_command.py", line 256, in _run_task_by_selected_method
    return _run_raw_task(args, ti)
           ^^^^^^^^^^^^^^^^^^^^^^^
  File "/home/airflow/.local/lib/python3.12/site-packages/airflow/cli/commands/task_command.py", line 341, in _run_raw_task
    return ti._run_raw_task(
           ^^^^^^^^^^^^^^^^^
  File "/home/airflow/.local/lib/python3.12/site-packages/airflow/utils/session.py", line 97, in wrapper
    return func(*args, session=session, **kwargs)
           ^^^^^^^^^^^^^^^^^^^^^^^^^^^^^^^^^^^^^^
  File "/home/airflow/.local/lib/python3.12/site-packages/airflow/models/taskinstance.py", line 3006, in _run_raw_task
    return _run_raw_task(
           ^^^^^^^^^^^^^^
  File "/home/airflow/.local/lib/python3.12/site-packages/airflow/models/taskinstance.py", line 274, in _run_raw_task
    TaskInstance._execute_task_with_callbacks(
  File "/home/airflow/.local/lib/python3.12/site-packages/airflow/models/taskinstance.py", line 3161, in _execute_task_with_callbacks
    result = self._execute_task(context, task_orig)
             ^^^^^^^^^^^^^^^^^^^^^^^^^^^^^^^^^^^^^^
  File "/home/airflow/.local/lib/python3.12/site-packages/airflow/models/taskinstance.py", line 3185, in _execute_task
    return _execute_task(self, context, task_orig)
           ^^^^^^^^^^^^^^^^^^^^^^^^^^^^^^^^^^^^^^^
  File "/home/airflow/.local/lib/python3.12/site-packages/airflow/models/taskinstance.py", line 768, in _execute_task
    result = _execute_callable(context=context, **execute_callable_kwargs)
             ^^^^^^^^^^^^^^^^^^^^^^^^^^^^^^^^^^^^^^^^^^^^^^^^^^^^^^^^^^^^^
  File "/home/airflow/.local/lib/python3.12/site-packages/airflow/models/taskinstance.py", line 734, in _execute_callable
    return ExecutionCallableRunner(
           ^^^^^^^^^^^^^^^^^^^^^^^^
  File "/home/airflow/.local/lib/python3.12/site-packages/airflow/utils/operator_helpers.py", line 252, in run
    return self.func(*args, **kwargs)
           ^^^^^^^^^^^^^^^^^^^^^^^^^^
  File "/home/airflow/.local/lib/python3.12/site-packages/airflow/models/baseoperator.py", line 424, in wrapper
    return func(self, *args, **kwargs)
           ^^^^^^^^^^^^^^^^^^^^^^^^^^^
  File "/home/airflow/.local/lib/python3.12/site-packages/airflow/operators/python.py", line 238, in execute
    return_value = self.execute_callable()
                   ^^^^^^^^^^^^^^^^^^^^^^^
  File "/home/airflow/.local/lib/python3.12/site-packages/airflow/operators/python.py", line 256, in execute_callable
    return runner.run(*self.op_args, **self.op_kwargs)
           ^^^^^^^^^^^^^^^^^^^^^^^^^^^^^^^^^^^^^^^^^^^
  File "/home/airflow/.local/lib/python3.12/site-packages/airflow/utils/operator_helpers.py", line 252, in run
    return self.func(*args, **kwargs)
           ^^^^^^^^^^^^^^^^^^^^^^^^^^
  File "/opt/airflow/dags/first_stage/first_stage.py", line 64, in gcs_destination
    upload_gcs_file(GCS_BUCKET_NAME, file_path, destination_blob_name)
  File "/opt/airflow/dags/first_stage/first_stage.py", line 28, in upload_gcs_file
    blob.upload_from_filename(source_file_name)
  File "/usr/local/lib/python3.12/contextlib.py", line 81, in inner
    return func(*args, **kwds)
           ^^^^^^^^^^^^^^^^^^^
  File "/home/airflow/.local/lib/python3.12/site-packages/google/cloud/storage/blob.py", line 3006, in upload_from_filename
    self._handle_filename_and_upload(
  File "/home/airflow/.local/lib/python3.12/site-packages/google/cloud/storage/blob.py", line 2884, in _handle_filename_and_upload
    self._prep_and_do_upload(
  File "/home/airflow/.local/lib/python3.12/site-packages/google/cloud/storage/blob.py", line 2700, in _prep_and_do_upload
    created_json = self._do_upload(
                   ^^^^^^^^^^^^^^^^
  File "/home/airflow/.local/lib/python3.12/site-packages/google/cloud/storage/blob.py", line 2523, in _do_upload
    response = self._do_resumable_upload(
               ^^^^^^^^^^^^^^^^^^^^^^^^^^
  File "/home/airflow/.local/lib/python3.12/site-packages/google/cloud/storage/blob.py", line 2359, in _do_resumable_upload
    response = upload.transmit_next_chunk(transport, timeout=timeout)
               ^^^^^^^^^^^^^^^^^^^^^^^^^^^^^^^^^^^^^^^^^^^^^^^^^^^^^^
  File "/home/airflow/.local/lib/python3.12/site-packages/google/resumable_media/requests/upload.py", line 515, in transmit_next_chunk
    return _request_helpers.wait_and_retry(
           ^^^^^^^^^^^^^^^^^^^^^^^^^^^^^^^^
  File "/home/airflow/.local/lib/python3.12/site-packages/google/resumable_media/requests/_request_helpers.py", line 178, in wait_and_retry
    raise error
  File "/home/airflow/.local/lib/python3.12/site-packages/google/resumable_media/requests/_request_helpers.py", line 155, in wait_and_retry
    response = func()
               ^^^^^^
  File "/home/airflow/.local/lib/python3.12/site-packages/google/resumable_media/requests/upload.py", line 507, in retriable_request
    result = transport.request(
             ^^^^^^^^^^^^^^^^^^
  File "/home/airflow/.local/lib/python3.12/site-packages/google/auth/transport/requests.py", line 537, in request
    response = super(AuthorizedSession, self).request(
               ^^^^^^^^^^^^^^^^^^^^^^^^^^^^^^^^^^^^^^^
  File "/home/airflow/.local/lib/python3.12/site-packages/requests/sessions.py", line 589, in request
    resp = self.send(prep, **send_kwargs)
           ^^^^^^^^^^^^^^^^^^^^^^^^^^^^^^
  File "/home/airflow/.local/lib/python3.12/site-packages/requests/sessions.py", line 703, in send
    r = adapter.send(request, **kwargs)
        ^^^^^^^^^^^^^^^^^^^^^^^^^^^^^^^
  File "/home/airflow/.local/lib/python3.12/site-packages/requests/adapters.py", line 682, in send
    raise ConnectionError(err, request=request)
requests.exceptions.ConnectionError: ('Connection aborted.', TimeoutError('The write operation timed out'))
[2025-04-13T19:40:10.611+0000] {local_task_job_runner.py:266} INFO - Task exited with return code 1
[2025-04-13T19:40:10.636+0000] {taskinstance.py:3901} INFO - 0 downstream tasks scheduled from follow-on schedule check
[2025-04-13T19:40:10.638+0000] {local_task_job_runner.py:245} INFO - ::endgroup::
