[2025-04-18T20:34:31.376+0000] {local_task_job_runner.py:123} INFO - ::group::Pre task execution logs
[2025-04-18T20:34:31.416+0000] {taskinstance.py:2614} INFO - Dependencies all met for dep_context=non-requeueable deps ti=<TaskInstance: run_dbt.run_dbt_all_models manual__2025-04-18T19:56:57.798037+00:00 [queued]>
[2025-04-18T20:34:31.442+0000] {taskinstance.py:2614} INFO - Dependencies all met for dep_context=requeueable deps ti=<TaskInstance: run_dbt.run_dbt_all_models manual__2025-04-18T19:56:57.798037+00:00 [queued]>
[2025-04-18T20:34:31.444+0000] {taskinstance.py:2867} INFO - Starting attempt 8 of 9
[2025-04-18T20:34:31.486+0000] {taskinstance.py:2890} INFO - Executing <Task(BashOperator): run_dbt_all_models> on 2025-04-18 19:56:57.798037+00:00
[2025-04-18T20:34:31.504+0000] {logging_mixin.py:190} WARNING - /home/***/.local/lib/python3.12/site-packages/***/task/task_runner/standard_task_runner.py:70 DeprecationWarning: This process (pid=44652) is multi-threaded, use of fork() may lead to deadlocks in the child.
[2025-04-18T20:34:31.507+0000] {standard_task_runner.py:72} INFO - Started process 44653 to run task
[2025-04-18T20:34:31.503+0000] {standard_task_runner.py:104} INFO - Running: ['***', 'tasks', 'run', 'run_dbt', 'run_dbt_all_models', 'manual__2025-04-18T19:56:57.798037+00:00', '--job-id', '642', '--raw', '--subdir', 'DAGS_FOLDER/run_dbt_model.py', '--cfg-path', '/tmp/tmpeglo6vxu']
[2025-04-18T20:34:31.511+0000] {standard_task_runner.py:105} INFO - Job 642: Subtask run_dbt_all_models
[2025-04-18T20:34:31.607+0000] {task_command.py:467} INFO - Running <TaskInstance: run_dbt.run_dbt_all_models manual__2025-04-18T19:56:57.798037+00:00 [running]> on host f21ba0bbe878
[2025-04-18T20:34:31.790+0000] {taskinstance.py:3134} INFO - Exporting env vars: AIRFLOW_CTX_DAG_OWNER='***' AIRFLOW_CTX_DAG_ID='run_dbt' AIRFLOW_CTX_TASK_ID='run_dbt_all_models' AIRFLOW_CTX_EXECUTION_DATE='2025-04-18T19:56:57.798037+00:00' AIRFLOW_CTX_TRY_NUMBER='8' AIRFLOW_CTX_DAG_RUN_ID='manual__2025-04-18T19:56:57.798037+00:00'
[2025-04-18T20:34:31.795+0000] {taskinstance.py:732} INFO - ::endgroup::
[2025-04-18T20:34:31.817+0000] {subprocess.py:78} INFO - Tmp dir root location: /tmp
[2025-04-18T20:34:31.818+0000] {subprocess.py:88} INFO - Running command: ['/usr/bin/bash', '-c', 'cd /opt/***/dbt && dbt run']
[2025-04-18T20:34:31.829+0000] {subprocess.py:99} INFO - Output:
[2025-04-18T20:34:35.966+0000] {subprocess.py:106} INFO - [0m20:34:35  Running with dbt=1.8.1
[2025-04-18T20:34:38.039+0000] {subprocess.py:106} INFO - [0m20:34:38  Registered adapter: bigquery=1.8.1
[2025-04-18T20:34:40.508+0000] {subprocess.py:106} INFO - [0m20:34:40  Found 1 seed, 10 models, 1 source, 602 macros
[2025-04-18T20:34:40.517+0000] {subprocess.py:106} INFO - [0m20:34:40
[2025-04-18T20:34:41.352+0000] {subprocess.py:106} INFO - [0m20:34:41  Concurrency: 1 threads (target='dev')
[2025-04-18T20:34:41.353+0000] {subprocess.py:106} INFO - [0m20:34:41
[2025-04-18T20:34:41.366+0000] {subprocess.py:106} INFO - [0m20:34:41  1 of 10 START sql table model db_project_dataset.dim_airports .................. [RUN]
[2025-04-18T20:34:43.619+0000] {subprocess.py:106} INFO - [0m20:34:43  1 of 10 OK created sql table model db_project_dataset.dim_airports ............. [[32mCREATE TABLE (3.4k rows, 141.3 KiB processed)[0m in 2.25s]
[2025-04-18T20:34:43.623+0000] {subprocess.py:106} INFO - [0m20:34:43  2 of 10 START sql view model db_project_dataset.stg_flights .................... [RUN]
[2025-04-18T20:34:44.505+0000] {subprocess.py:106} INFO - [0m20:34:44  2 of 10 OK created sql view model db_project_dataset.stg_flights ............... [[32mCREATE VIEW (0 processed)[0m in 0.88s]
[2025-04-18T20:34:44.512+0000] {subprocess.py:106} INFO - [0m20:34:44  3 of 10 START sql table model db_project_dataset.core_flights .................. [RUN]
[2025-04-18T20:34:46.947+0000] {subprocess.py:106} INFO - [0m20:34:46  BigQuery adapter: https://console.cloud.google.com/bigquery?project=db-project-456518&j=bq:europe-central2:d8359e30-fb1d-4ca4-a619-6f1b6c7da03a&page=queryresults
[2025-04-18T20:34:46.959+0000] {subprocess.py:106} INFO - [0m20:34:46  3 of 10 ERROR creating sql table model db_project_dataset.core_flights ......... [[31mERROR[0m in 2.44s]
[2025-04-18T20:34:46.965+0000] {subprocess.py:106} INFO - [0m20:34:46  4 of 10 SKIP relation db_project_dataset.dim_carriers .......................... [[33mSKIP[0m]
[2025-04-18T20:34:46.968+0000] {subprocess.py:106} INFO - [0m20:34:46  5 of 10 SKIP relation db_project_dataset.dim_dates ............................. [[33mSKIP[0m]
[2025-04-18T20:34:46.972+0000] {subprocess.py:106} INFO - [0m20:34:46  6 of 10 SKIP relation db_project_dataset.fact_delays_by_flight_num ............. [[33mSKIP[0m]
[2025-04-18T20:34:46.975+0000] {subprocess.py:106} INFO - [0m20:34:46  7 of 10 SKIP relation db_project_dataset.fact_delays_departure_by_airport ...... [[33mSKIP[0m]
[2025-04-18T20:34:46.978+0000] {subprocess.py:106} INFO - [0m20:34:46  8 of 10 SKIP relation db_project_dataset.fact_departures.by_year ............... [[33mSKIP[0m]
[2025-04-18T20:34:46.981+0000] {subprocess.py:106} INFO - [0m20:34:46  9 of 10 SKIP relation db_project_dataset.fact_departures_by_airport_year ....... [[33mSKIP[0m]
[2025-04-18T20:34:46.984+0000] {subprocess.py:106} INFO - [0m20:34:46  10 of 10 SKIP relation db_project_dataset.fact_most_departures_airport ......... [[33mSKIP[0m]
[2025-04-18T20:34:46.990+0000] {subprocess.py:106} INFO - [0m20:34:46
[2025-04-18T20:34:46.991+0000] {subprocess.py:106} INFO - [0m20:34:46  Finished running 9 table models, 1 view model in 0 hours 0 minutes and 6.47 seconds (6.47s).
[2025-04-18T20:34:47.094+0000] {subprocess.py:106} INFO - [0m20:34:47
[2025-04-18T20:34:47.095+0000] {subprocess.py:106} INFO - [0m20:34:47  [31mCompleted with 1 error and 0 warnings:[0m
[2025-04-18T20:34:47.096+0000] {subprocess.py:106} INFO - [0m20:34:47
[2025-04-18T20:34:47.097+0000] {subprocess.py:106} INFO - [0m20:34:47    Database Error in model core_flights (models/core/core_flights.sql)
[2025-04-18T20:34:47.098+0000] {subprocess.py:106} INFO -   Invalid timestamp: '1999-07-09 17:43'
[2025-04-18T20:34:47.098+0000] {subprocess.py:106} INFO -   compiled code at target/run/flights_project/models/core/core_flights.sql
[2025-04-18T20:34:47.099+0000] {subprocess.py:106} INFO - [0m20:34:47
[2025-04-18T20:34:47.099+0000] {subprocess.py:106} INFO - [0m20:34:47  Done. PASS=2 WARN=0 ERROR=1 SKIP=7 TOTAL=10
[2025-04-18T20:34:48.640+0000] {subprocess.py:110} INFO - Command exited with return code 1
[2025-04-18T20:34:48.652+0000] {taskinstance.py:3313} ERROR - Task failed with exception
Traceback (most recent call last):
  File "/home/airflow/.local/lib/python3.12/site-packages/airflow/models/taskinstance.py", line 768, in _execute_task
    result = _execute_callable(context=context, **execute_callable_kwargs)
             ^^^^^^^^^^^^^^^^^^^^^^^^^^^^^^^^^^^^^^^^^^^^^^^^^^^^^^^^^^^^^
  File "/home/airflow/.local/lib/python3.12/site-packages/airflow/models/taskinstance.py", line 734, in _execute_callable
    return ExecutionCallableRunner(
           ^^^^^^^^^^^^^^^^^^^^^^^^
  File "/home/airflow/.local/lib/python3.12/site-packages/airflow/utils/operator_helpers.py", line 252, in run
    return self.func(*args, **kwargs)
           ^^^^^^^^^^^^^^^^^^^^^^^^^^
  File "/home/airflow/.local/lib/python3.12/site-packages/airflow/models/baseoperator.py", line 424, in wrapper
    return func(self, *args, **kwargs)
           ^^^^^^^^^^^^^^^^^^^^^^^^^^^
  File "/home/airflow/.local/lib/python3.12/site-packages/airflow/operators/bash.py", line 276, in execute
    raise AirflowException(
airflow.exceptions.AirflowException: Bash command failed. The command returned a non-zero exit code 1.
[2025-04-18T20:34:48.661+0000] {taskinstance.py:1226} INFO - Marking task as UP_FOR_RETRY. dag_id=run_dbt, task_id=run_dbt_all_models, run_id=manual__2025-04-18T19:56:57.798037+00:00, execution_date=20250418T195657, start_date=20250418T203431, end_date=20250418T203448
[2025-04-18T20:34:48.712+0000] {taskinstance.py:341} INFO - ::group::Post task execution logs
[2025-04-18T20:34:48.713+0000] {standard_task_runner.py:124} ERROR - Failed to execute job 642 for task run_dbt_all_models (Bash command failed. The command returned a non-zero exit code 1.; 44653)
Traceback (most recent call last):
  File "/home/airflow/.local/lib/python3.12/site-packages/airflow/task/task_runner/standard_task_runner.py", line 117, in _start_by_fork
    ret = args.func(args, dag=self.dag)
          ^^^^^^^^^^^^^^^^^^^^^^^^^^^^^
  File "/home/airflow/.local/lib/python3.12/site-packages/airflow/cli/cli_config.py", line 49, in command
    return func(*args, **kwargs)
           ^^^^^^^^^^^^^^^^^^^^^
  File "/home/airflow/.local/lib/python3.12/site-packages/airflow/utils/cli.py", line 116, in wrapper
    return f(*args, **kwargs)
           ^^^^^^^^^^^^^^^^^^
  File "/home/airflow/.local/lib/python3.12/site-packages/airflow/cli/commands/task_command.py", line 483, in task_run
    task_return_code = _run_task_by_selected_method(args, _dag, ti)
                       ^^^^^^^^^^^^^^^^^^^^^^^^^^^^^^^^^^^^^^^^^^^^
  File "/home/airflow/.local/lib/python3.12/site-packages/airflow/cli/commands/task_command.py", line 256, in _run_task_by_selected_method
    return _run_raw_task(args, ti)
           ^^^^^^^^^^^^^^^^^^^^^^^
  File "/home/airflow/.local/lib/python3.12/site-packages/airflow/cli/commands/task_command.py", line 341, in _run_raw_task
    return ti._run_raw_task(
           ^^^^^^^^^^^^^^^^^
  File "/home/airflow/.local/lib/python3.12/site-packages/airflow/utils/session.py", line 97, in wrapper
    return func(*args, session=session, **kwargs)
           ^^^^^^^^^^^^^^^^^^^^^^^^^^^^^^^^^^^^^^
  File "/home/airflow/.local/lib/python3.12/site-packages/airflow/models/taskinstance.py", line 3006, in _run_raw_task
    return _run_raw_task(
           ^^^^^^^^^^^^^^
  File "/home/airflow/.local/lib/python3.12/site-packages/airflow/models/taskinstance.py", line 274, in _run_raw_task
    TaskInstance._execute_task_with_callbacks(
  File "/home/airflow/.local/lib/python3.12/site-packages/airflow/models/taskinstance.py", line 3161, in _execute_task_with_callbacks
    result = self._execute_task(context, task_orig)
             ^^^^^^^^^^^^^^^^^^^^^^^^^^^^^^^^^^^^^^
  File "/home/airflow/.local/lib/python3.12/site-packages/airflow/models/taskinstance.py", line 3185, in _execute_task
    return _execute_task(self, context, task_orig)
           ^^^^^^^^^^^^^^^^^^^^^^^^^^^^^^^^^^^^^^^
  File "/home/airflow/.local/lib/python3.12/site-packages/airflow/models/taskinstance.py", line 768, in _execute_task
    result = _execute_callable(context=context, **execute_callable_kwargs)
             ^^^^^^^^^^^^^^^^^^^^^^^^^^^^^^^^^^^^^^^^^^^^^^^^^^^^^^^^^^^^^
  File "/home/airflow/.local/lib/python3.12/site-packages/airflow/models/taskinstance.py", line 734, in _execute_callable
    return ExecutionCallableRunner(
           ^^^^^^^^^^^^^^^^^^^^^^^^
  File "/home/airflow/.local/lib/python3.12/site-packages/airflow/utils/operator_helpers.py", line 252, in run
    return self.func(*args, **kwargs)
           ^^^^^^^^^^^^^^^^^^^^^^^^^^
  File "/home/airflow/.local/lib/python3.12/site-packages/airflow/models/baseoperator.py", line 424, in wrapper
    return func(self, *args, **kwargs)
           ^^^^^^^^^^^^^^^^^^^^^^^^^^^
  File "/home/airflow/.local/lib/python3.12/site-packages/airflow/operators/bash.py", line 276, in execute
    raise AirflowException(
airflow.exceptions.AirflowException: Bash command failed. The command returned a non-zero exit code 1.
[2025-04-18T20:34:48.732+0000] {local_task_job_runner.py:266} INFO - Task exited with return code 1
[2025-04-18T20:34:48.763+0000] {taskinstance.py:3901} INFO - 0 downstream tasks scheduled from follow-on schedule check
[2025-04-18T20:34:48.767+0000] {local_task_job_runner.py:245} INFO - ::endgroup::
