[2025-04-14T16:59:17.331+0000] {local_task_job_runner.py:123} INFO - ::group::Pre task execution logs
[2025-04-14T16:59:17.350+0000] {taskinstance.py:2614} INFO - Dependencies all met for dep_context=non-requeueable deps ti=<TaskInstance: dbt_airflow.run_dbt_staging manual__2025-04-14T15:18:53.940263+00:00 [queued]>
[2025-04-14T16:59:17.360+0000] {taskinstance.py:2614} INFO - Dependencies all met for dep_context=requeueable deps ti=<TaskInstance: dbt_airflow.run_dbt_staging manual__2025-04-14T15:18:53.940263+00:00 [queued]>
[2025-04-14T16:59:17.361+0000] {taskinstance.py:2867} INFO - Starting attempt 6 of 7
[2025-04-14T16:59:17.376+0000] {taskinstance.py:2890} INFO - Executing <Task(BashOperator): run_dbt_staging> on 2025-04-14 15:18:53.940263+00:00
[2025-04-14T16:59:17.385+0000] {logging_mixin.py:190} WARNING - /home/***/.local/lib/python3.12/site-packages/***/task/task_runner/standard_task_runner.py:70 DeprecationWarning: This process (pid=12645) is multi-threaded, use of fork() may lead to deadlocks in the child.
[2025-04-14T16:59:17.384+0000] {standard_task_runner.py:104} INFO - Running: ['***', 'tasks', 'run', 'dbt_***', 'run_dbt_staging', 'manual__2025-04-14T15:18:53.940263+00:00', '--job-id', '504', '--raw', '--subdir', 'DAGS_FOLDER/run_dbt_model.py', '--cfg-path', '/tmp/tmpl08tbxlu']
[2025-04-14T16:59:17.386+0000] {standard_task_runner.py:72} INFO - Started process 12646 to run task
[2025-04-14T16:59:17.387+0000] {standard_task_runner.py:105} INFO - Job 504: Subtask run_dbt_staging
[2025-04-14T16:59:17.438+0000] {task_command.py:467} INFO - Running <TaskInstance: dbt_airflow.run_dbt_staging manual__2025-04-14T15:18:53.940263+00:00 [running]> on host b7be566335ce
[2025-04-14T16:59:17.516+0000] {taskinstance.py:3134} INFO - Exporting env vars: AIRFLOW_CTX_DAG_OWNER='***' AIRFLOW_CTX_DAG_ID='dbt_***' AIRFLOW_CTX_TASK_ID='run_dbt_staging' AIRFLOW_CTX_EXECUTION_DATE='2025-04-14T15:18:53.940263+00:00' AIRFLOW_CTX_TRY_NUMBER='6' AIRFLOW_CTX_DAG_RUN_ID='manual__2025-04-14T15:18:53.940263+00:00'
[2025-04-14T16:59:17.517+0000] {taskinstance.py:732} INFO - ::endgroup::
[2025-04-14T16:59:17.539+0000] {subprocess.py:78} INFO - Tmp dir root location: /tmp
[2025-04-14T16:59:17.540+0000] {subprocess.py:88} INFO - Running command: ['/usr/bin/bash', '-c', 'cd /opt/***/dbt && dbt deps && dbt run --models stg_flights']
[2025-04-14T16:59:17.552+0000] {subprocess.py:99} INFO - Output:
[2025-04-14T16:59:21.925+0000] {subprocess.py:106} INFO - [0m16:59:21  Running with dbt=1.7.9
[2025-04-14T16:59:22.850+0000] {subprocess.py:106} INFO - [0m16:59:22  Installing dbt-labs/dbt_utils
[2025-04-14T16:59:26.828+0000] {subprocess.py:106} INFO - [0m16:59:26  Installed from version 1.3.0
[2025-04-14T16:59:26.829+0000] {subprocess.py:106} INFO - [0m16:59:26  Up to date!
[2025-04-14T16:59:33.080+0000] {subprocess.py:106} INFO - [0m16:59:33  Running with dbt=1.7.9
[2025-04-14T16:59:35.333+0000] {subprocess.py:106} INFO - [0m16:59:35  Registered adapter: bigquery=1.7.9
[2025-04-14T16:59:36.739+0000] {subprocess.py:106} INFO - [0m16:59:36  Found 1 seed, 2 models, 1 source, 0 exposures, 0 metrics, 571 macros, 0 groups, 0 semantic models
[2025-04-14T16:59:36.747+0000] {subprocess.py:106} INFO - [0m16:59:36
[2025-04-14T16:59:37.541+0000] {subprocess.py:106} INFO - [0m16:59:37  Concurrency: 1 threads (target='dev')
[2025-04-14T16:59:37.542+0000] {subprocess.py:106} INFO - [0m16:59:37
[2025-04-14T16:59:37.558+0000] {subprocess.py:106} INFO - [0m16:59:37  1 of 1 START sql view model db_project_dataset.stg_flights ..................... [RUN]
[2025-04-14T16:59:39.213+0000] {subprocess.py:106} INFO - [0m16:59:39  BigQuery adapter: https://console.cloud.google.com/bigquery?project=db-project-456518&j=bq:US:abbae7cd-3594-4819-ab0d-ec1fd48f1aca&page=queryresults
[2025-04-14T16:59:39.235+0000] {subprocess.py:106} INFO - [0m16:59:39  1 of 1 ERROR creating sql view model db_project_dataset.stg_flights ............ [[31mERROR[0m in 1.67s]
[2025-04-14T16:59:39.246+0000] {subprocess.py:106} INFO - [0m16:59:39
[2025-04-14T16:59:39.247+0000] {subprocess.py:106} INFO - [0m16:59:39  Finished running 1 view model in 0 hours 0 minutes and 2.50 seconds (2.50s).
[2025-04-14T16:59:39.280+0000] {subprocess.py:106} INFO - [0m16:59:39
[2025-04-14T16:59:39.282+0000] {subprocess.py:106} INFO - [0m16:59:39  [31mCompleted with 1 error and 0 warnings:[0m
[2025-04-14T16:59:39.284+0000] {subprocess.py:106} INFO - [0m16:59:39
[2025-04-14T16:59:39.287+0000] {subprocess.py:106} INFO - [0m16:59:39    Database Error in model stg_flights (models/stg_flights.sql)
[2025-04-14T16:59:39.288+0000] {subprocess.py:106} INFO -   Syntax error: Expected end of input but got keyword CASE at [25:5]
[2025-04-14T16:59:39.288+0000] {subprocess.py:106} INFO -   compiled Code at target/run/flights_project/models/stg_flights.sql
[2025-04-14T16:59:39.289+0000] {subprocess.py:106} INFO - [0m16:59:39
[2025-04-14T16:59:39.290+0000] {subprocess.py:106} INFO - [0m16:59:39  Done. PASS=0 WARN=0 ERROR=1 SKIP=0 TOTAL=1
[2025-04-14T16:59:40.531+0000] {subprocess.py:110} INFO - Command exited with return code 1
[2025-04-14T16:59:40.546+0000] {taskinstance.py:3313} ERROR - Task failed with exception
Traceback (most recent call last):
  File "/home/airflow/.local/lib/python3.12/site-packages/airflow/models/taskinstance.py", line 768, in _execute_task
    result = _execute_callable(context=context, **execute_callable_kwargs)
             ^^^^^^^^^^^^^^^^^^^^^^^^^^^^^^^^^^^^^^^^^^^^^^^^^^^^^^^^^^^^^
  File "/home/airflow/.local/lib/python3.12/site-packages/airflow/models/taskinstance.py", line 734, in _execute_callable
    return ExecutionCallableRunner(
           ^^^^^^^^^^^^^^^^^^^^^^^^
  File "/home/airflow/.local/lib/python3.12/site-packages/airflow/utils/operator_helpers.py", line 252, in run
    return self.func(*args, **kwargs)
           ^^^^^^^^^^^^^^^^^^^^^^^^^^
  File "/home/airflow/.local/lib/python3.12/site-packages/airflow/models/baseoperator.py", line 424, in wrapper
    return func(self, *args, **kwargs)
           ^^^^^^^^^^^^^^^^^^^^^^^^^^^
  File "/home/airflow/.local/lib/python3.12/site-packages/airflow/operators/bash.py", line 276, in execute
    raise AirflowException(
airflow.exceptions.AirflowException: Bash command failed. The command returned a non-zero exit code 1.
[2025-04-14T16:59:40.556+0000] {taskinstance.py:1226} INFO - Marking task as UP_FOR_RETRY. dag_id=dbt_***, task_id=run_dbt_staging, run_id=manual__2025-04-14T15:18:53.940263+00:00, execution_date=20250414T151853, start_date=20250414T165917, end_date=20250414T165940
[2025-04-14T16:59:40.597+0000] {taskinstance.py:341} INFO - ::group::Post task execution logs
[2025-04-14T16:59:40.598+0000] {standard_task_runner.py:124} ERROR - Failed to execute job 504 for task run_dbt_staging (Bash command failed. The command returned a non-zero exit code 1.; 12646)
Traceback (most recent call last):
  File "/home/airflow/.local/lib/python3.12/site-packages/airflow/task/task_runner/standard_task_runner.py", line 117, in _start_by_fork
    ret = args.func(args, dag=self.dag)
          ^^^^^^^^^^^^^^^^^^^^^^^^^^^^^
  File "/home/airflow/.local/lib/python3.12/site-packages/airflow/cli/cli_config.py", line 49, in command
    return func(*args, **kwargs)
           ^^^^^^^^^^^^^^^^^^^^^
  File "/home/airflow/.local/lib/python3.12/site-packages/airflow/utils/cli.py", line 116, in wrapper
    return f(*args, **kwargs)
           ^^^^^^^^^^^^^^^^^^
  File "/home/airflow/.local/lib/python3.12/site-packages/airflow/cli/commands/task_command.py", line 483, in task_run
    task_return_code = _run_task_by_selected_method(args, _dag, ti)
                       ^^^^^^^^^^^^^^^^^^^^^^^^^^^^^^^^^^^^^^^^^^^^
  File "/home/airflow/.local/lib/python3.12/site-packages/airflow/cli/commands/task_command.py", line 256, in _run_task_by_selected_method
    return _run_raw_task(args, ti)
           ^^^^^^^^^^^^^^^^^^^^^^^
  File "/home/airflow/.local/lib/python3.12/site-packages/airflow/cli/commands/task_command.py", line 341, in _run_raw_task
    return ti._run_raw_task(
           ^^^^^^^^^^^^^^^^^
  File "/home/airflow/.local/lib/python3.12/site-packages/airflow/utils/session.py", line 97, in wrapper
    return func(*args, session=session, **kwargs)
           ^^^^^^^^^^^^^^^^^^^^^^^^^^^^^^^^^^^^^^
  File "/home/airflow/.local/lib/python3.12/site-packages/airflow/models/taskinstance.py", line 3006, in _run_raw_task
    return _run_raw_task(
           ^^^^^^^^^^^^^^
  File "/home/airflow/.local/lib/python3.12/site-packages/airflow/models/taskinstance.py", line 274, in _run_raw_task
    TaskInstance._execute_task_with_callbacks(
  File "/home/airflow/.local/lib/python3.12/site-packages/airflow/models/taskinstance.py", line 3161, in _execute_task_with_callbacks
    result = self._execute_task(context, task_orig)
             ^^^^^^^^^^^^^^^^^^^^^^^^^^^^^^^^^^^^^^
  File "/home/airflow/.local/lib/python3.12/site-packages/airflow/models/taskinstance.py", line 3185, in _execute_task
    return _execute_task(self, context, task_orig)
           ^^^^^^^^^^^^^^^^^^^^^^^^^^^^^^^^^^^^^^^
  File "/home/airflow/.local/lib/python3.12/site-packages/airflow/models/taskinstance.py", line 768, in _execute_task
    result = _execute_callable(context=context, **execute_callable_kwargs)
             ^^^^^^^^^^^^^^^^^^^^^^^^^^^^^^^^^^^^^^^^^^^^^^^^^^^^^^^^^^^^^
  File "/home/airflow/.local/lib/python3.12/site-packages/airflow/models/taskinstance.py", line 734, in _execute_callable
    return ExecutionCallableRunner(
           ^^^^^^^^^^^^^^^^^^^^^^^^
  File "/home/airflow/.local/lib/python3.12/site-packages/airflow/utils/operator_helpers.py", line 252, in run
    return self.func(*args, **kwargs)
           ^^^^^^^^^^^^^^^^^^^^^^^^^^
  File "/home/airflow/.local/lib/python3.12/site-packages/airflow/models/baseoperator.py", line 424, in wrapper
    return func(self, *args, **kwargs)
           ^^^^^^^^^^^^^^^^^^^^^^^^^^^
  File "/home/airflow/.local/lib/python3.12/site-packages/airflow/operators/bash.py", line 276, in execute
    raise AirflowException(
airflow.exceptions.AirflowException: Bash command failed. The command returned a non-zero exit code 1.
[2025-04-14T16:59:40.638+0000] {local_task_job_runner.py:266} INFO - Task exited with return code 1
[2025-04-14T16:59:40.665+0000] {taskinstance.py:3901} INFO - 0 downstream tasks scheduled from follow-on schedule check
[2025-04-14T16:59:40.668+0000] {local_task_job_runner.py:245} INFO - ::endgroup::
