[2025-04-13T19:47:16.240+0000] {local_task_job_runner.py:123} INFO - ::group::Pre task execution logs
[2025-04-13T19:47:16.502+0000] {taskinstance.py:2614} INFO - Dependencies all met for dep_context=non-requeueable deps ti=<TaskInstance: gcs_dlt_data_pipeline.download_file scheduled__1992-01-01T00:00:00+00:00 [queued]>
[2025-04-13T19:47:16.563+0000] {taskinstance.py:2614} INFO - Dependencies all met for dep_context=requeueable deps ti=<TaskInstance: gcs_dlt_data_pipeline.download_file scheduled__1992-01-01T00:00:00+00:00 [queued]>
[2025-04-13T19:47:16.566+0000] {taskinstance.py:2867} INFO - Starting attempt 1 of 2
[2025-04-13T19:47:16.859+0000] {taskinstance.py:2890} INFO - Executing <Task(PythonOperator): download_file> on 1992-01-01 00:00:00+00:00
[2025-04-13T19:47:17.328+0000] {logging_mixin.py:190} WARNING - /home/***/.local/lib/python3.12/site-packages/***/task/task_runner/standard_task_runner.py:70 DeprecationWarning: This process (pid=1685) is multi-threaded, use of fork() may lead to deadlocks in the child.
[2025-04-13T19:47:17.427+0000] {standard_task_runner.py:72} INFO - Started process 1713 to run task
[2025-04-13T19:47:17.361+0000] {standard_task_runner.py:104} INFO - Running: ['***', 'tasks', 'run', 'gcs_dlt_data_pipeline', 'download_file', 'scheduled__1992-01-01T00:00:00+00:00', '--job-id', '171', '--raw', '--subdir', 'DAGS_FOLDER/first_stage/first_stage.py', '--cfg-path', '/tmp/tmpbienxeny']
[2025-04-13T19:47:17.586+0000] {standard_task_runner.py:105} INFO - Job 171: Subtask download_file
[2025-04-13T19:47:19.075+0000] {task_command.py:467} INFO - Running <TaskInstance: gcs_dlt_data_pipeline.download_file scheduled__1992-01-01T00:00:00+00:00 [running]> on host 0728476a73c7
[2025-04-13T19:47:20.614+0000] {taskinstance.py:3134} INFO - Exporting env vars: AIRFLOW_CTX_DAG_OWNER='***' AIRFLOW_CTX_DAG_ID='gcs_dlt_data_pipeline' AIRFLOW_CTX_TASK_ID='download_file' AIRFLOW_CTX_EXECUTION_DATE='1992-01-01T00:00:00+00:00' AIRFLOW_CTX_TRY_NUMBER='1' AIRFLOW_CTX_DAG_RUN_ID='scheduled__1992-01-01T00:00:00+00:00'
[2025-04-13T19:47:20.630+0000] {taskinstance.py:732} INFO - ::endgroup::
[2025-04-13T19:47:20.732+0000] {logging_mixin.py:190} INFO - Source File Path: raw/1992.csv.bz2
[2025-04-13T19:47:20.739+0000] {logging_mixin.py:190} INFO - Destination File Path: /tmp/1992.csv.bz2
[2025-04-13T19:47:20.747+0000] {logging_mixin.py:190} INFO - Downloading raw/1992.csv.bz2 from bucket db_project_data_bucket to /tmp/1992.csv.bz2
[2025-04-13T19:47:31.137+0000] {connectionpool.py:827} WARNING - Retrying (Retry(total=2, connect=None, read=None, redirect=None, status=None)) after connection broken by 'NewConnectionError('<urllib3.connection.HTTPSConnection object at 0x7f95259caa80>: Failed to establish a new connection: [Errno -3] Temporary failure in name resolution')': /token
[2025-04-13T19:47:46.439+0000] {connectionpool.py:827} WARNING - Retrying (Retry(total=1, connect=None, read=None, redirect=None, status=None)) after connection broken by 'NewConnectionError('<urllib3.connection.HTTPSConnection object at 0x7f9525173830>: Failed to establish a new connection: [Errno -3] Temporary failure in name resolution')': /token
[2025-04-13T19:47:51.938+0000] {job.py:229} INFO - Heartbeat recovered after 29.29 seconds
[2025-04-13T19:48:45.830+0000] {local_task_job_runner.py:127} ERROR - Received SIGTERM. Terminating subprocesses
