[2025-04-14T17:21:41.000+0000] {local_task_job_runner.py:123} INFO - ::group::Pre task execution logs
[2025-04-14T17:21:41.025+0000] {taskinstance.py:2614} INFO - Dependencies all met for dep_context=non-requeueable deps ti=<TaskInstance: dbt_airflow.run_dbt_marts manual__2025-04-14T15:18:53.940263+00:00 [queued]>
[2025-04-14T17:21:41.039+0000] {taskinstance.py:2614} INFO - Dependencies all met for dep_context=requeueable deps ti=<TaskInstance: dbt_airflow.run_dbt_marts manual__2025-04-14T15:18:53.940263+00:00 [queued]>
[2025-04-14T17:21:41.040+0000] {taskinstance.py:2867} INFO - Starting attempt 2 of 3
[2025-04-14T17:21:41.068+0000] {taskinstance.py:2890} INFO - Executing <Task(BashOperator): run_dbt_marts> on 2025-04-14 15:18:53.940263+00:00
[2025-04-14T17:21:41.084+0000] {standard_task_runner.py:104} INFO - Running: ['***', 'tasks', 'run', 'dbt_***', 'run_dbt_marts', 'manual__2025-04-14T15:18:53.940263+00:00', '--job-id', '515', '--raw', '--subdir', 'DAGS_FOLDER/run_dbt_model.py', '--cfg-path', '/tmp/tmpqg56w4mw']
[2025-04-14T17:21:41.089+0000] {standard_task_runner.py:105} INFO - Job 515: Subtask run_dbt_marts
[2025-04-14T17:21:41.478+0000] {logging_mixin.py:190} WARNING - /home/***/.local/lib/python3.12/site-packages/***/task/task_runner/standard_task_runner.py:70 DeprecationWarning: This process (pid=13864) is multi-threaded, use of fork() may lead to deadlocks in the child.
[2025-04-14T17:21:41.479+0000] {standard_task_runner.py:72} INFO - Started process 13865 to run task
[2025-04-14T17:21:41.518+0000] {task_command.py:467} INFO - Running <TaskInstance: dbt_airflow.run_dbt_marts manual__2025-04-14T15:18:53.940263+00:00 [running]> on host b7be566335ce
[2025-04-14T17:21:41.630+0000] {taskinstance.py:3134} INFO - Exporting env vars: AIRFLOW_CTX_DAG_OWNER='***' AIRFLOW_CTX_DAG_ID='dbt_***' AIRFLOW_CTX_TASK_ID='run_dbt_marts' AIRFLOW_CTX_EXECUTION_DATE='2025-04-14T15:18:53.940263+00:00' AIRFLOW_CTX_TRY_NUMBER='2' AIRFLOW_CTX_DAG_RUN_ID='manual__2025-04-14T15:18:53.940263+00:00'
[2025-04-14T17:21:41.631+0000] {taskinstance.py:732} INFO - ::endgroup::
[2025-04-14T17:21:41.661+0000] {subprocess.py:78} INFO - Tmp dir root location: /tmp
[2025-04-14T17:21:41.664+0000] {subprocess.py:88} INFO - Running command: ['/usr/bin/bash', '-c', 'cd /opt/***/dbt && dbt run --models fact_departures_by_airport_year']
[2025-04-14T17:21:41.682+0000] {subprocess.py:99} INFO - Output:
[2025-04-14T17:21:49.379+0000] {subprocess.py:106} INFO - [0m17:21:49  Running with dbt=1.7.9
[2025-04-14T17:21:55.037+0000] {subprocess.py:106} INFO - [0m17:21:55  Registered adapter: bigquery=1.7.9
[2025-04-14T17:21:56.369+0000] {subprocess.py:106} INFO - [0m17:21:56  Found 1 seed, 3 models, 1 source, 0 exposures, 0 metrics, 571 macros, 0 groups, 0 semantic models
[2025-04-14T17:21:56.372+0000] {subprocess.py:106} INFO - [0m17:21:56
[2025-04-14T17:21:57.264+0000] {subprocess.py:106} INFO - [0m17:21:57  Concurrency: 1 threads (target='dev')
[2025-04-14T17:21:57.265+0000] {subprocess.py:106} INFO - [0m17:21:57
[2025-04-14T17:21:57.278+0000] {subprocess.py:106} INFO - [0m17:21:57  1 of 1 START sql table model db_project_dataset.fact_departures_by_airport_year  [RUN]
[2025-04-14T17:21:59.226+0000] {subprocess.py:106} INFO - [0m17:21:59  BigQuery adapter: https://console.cloud.google.com/bigquery?project=db-project-456518&j=bq:europe-central2:87120f91-9070-4006-b85c-3f692e5953da&page=queryresults
[2025-04-14T17:21:59.243+0000] {subprocess.py:106} INFO - [0m17:21:59  1 of 1 ERROR creating sql table model db_project_dataset.fact_departures_by_airport_year  [[31mERROR[0m in 1.96s]
[2025-04-14T17:21:59.254+0000] {subprocess.py:106} INFO - [0m17:21:59
[2025-04-14T17:21:59.256+0000] {subprocess.py:106} INFO - [0m17:21:59  Finished running 1 table model in 0 hours 0 minutes and 2.88 seconds (2.88s).
[2025-04-14T17:21:59.307+0000] {subprocess.py:106} INFO - [0m17:21:59
[2025-04-14T17:21:59.308+0000] {subprocess.py:106} INFO - [0m17:21:59  [31mCompleted with 1 error and 0 warnings:[0m
[2025-04-14T17:21:59.310+0000] {subprocess.py:106} INFO - [0m17:21:59
[2025-04-14T17:21:59.317+0000] {subprocess.py:106} INFO - [0m17:21:59    Database Error in model fact_departures_by_airport_year (models/marts/fact_departures_by_airport_year.sql)
[2025-04-14T17:21:59.318+0000] {subprocess.py:106} INFO -   No matching signature for function EXTRACT for argument types: DATE_TIME_PART FROM STRING
[2025-04-14T17:21:59.319+0000] {subprocess.py:106} INFO -     Signature: EXTRACT(DATE_TIME_PART FROM DATE)
[2025-04-14T17:21:59.320+0000] {subprocess.py:106} INFO -       Argument 1: Unable to coerce type STRING to expected type DATE
[2025-04-14T17:21:59.321+0000] {subprocess.py:106} INFO -     Signature: EXTRACT(DATE_TIME_PART FROM TIMESTAMP [AT TIME ZONE STRING])
[2025-04-14T17:21:59.322+0000] {subprocess.py:106} INFO -       Argument 1: Unable to coerce type STRING to expected type TIMESTAMP
[2025-04-14T17:21:59.323+0000] {subprocess.py:106} INFO -     Signature: EXTRACT(DATE_TIME_PART FROM DATETIME)
[2025-04-14T17:21:59.324+0000] {subprocess.py:106} INFO -       Argument 1: Unable to coerce type STRING to expected type DATETIME
[2025-04-14T17:21:59.325+0000] {subprocess.py:106} INFO -     Signature: EXTRACT(DATE_TIME_PART FROM TIME)
[2025-04-14T17:21:59.326+0000] {subprocess.py:106} INFO -       Argument 1: Unable to coerce type STRING to expected type TIME
[2025-04-14T17:21:59.327+0000] {subprocess.py:106} INFO -     Signature: EXTRACT(DATE_TIME_PART FROM INTERVAL)
[2025-04-14T17:21:59.328+0000] {subprocess.py:106} INFO -       Argument 1: Unable to coerce type STRING to expected type INTERVAL at [22:5]
[2025-04-14T17:21:59.330+0000] {subprocess.py:106} INFO -   compiled Code at target/run/flights_project/models/marts/fact_departures_by_airport_year.sql
[2025-04-14T17:21:59.331+0000] {subprocess.py:106} INFO - [0m17:21:59
[2025-04-14T17:21:59.333+0000] {subprocess.py:106} INFO - [0m17:21:59  Done. PASS=0 WARN=0 ERROR=1 SKIP=0 TOTAL=1
[2025-04-14T17:22:00.340+0000] {subprocess.py:110} INFO - Command exited with return code 1
[2025-04-14T17:22:00.352+0000] {taskinstance.py:3313} ERROR - Task failed with exception
Traceback (most recent call last):
  File "/home/airflow/.local/lib/python3.12/site-packages/airflow/models/taskinstance.py", line 768, in _execute_task
    result = _execute_callable(context=context, **execute_callable_kwargs)
             ^^^^^^^^^^^^^^^^^^^^^^^^^^^^^^^^^^^^^^^^^^^^^^^^^^^^^^^^^^^^^
  File "/home/airflow/.local/lib/python3.12/site-packages/airflow/models/taskinstance.py", line 734, in _execute_callable
    return ExecutionCallableRunner(
           ^^^^^^^^^^^^^^^^^^^^^^^^
  File "/home/airflow/.local/lib/python3.12/site-packages/airflow/utils/operator_helpers.py", line 252, in run
    return self.func(*args, **kwargs)
           ^^^^^^^^^^^^^^^^^^^^^^^^^^
  File "/home/airflow/.local/lib/python3.12/site-packages/airflow/models/baseoperator.py", line 424, in wrapper
    return func(self, *args, **kwargs)
           ^^^^^^^^^^^^^^^^^^^^^^^^^^^
  File "/home/airflow/.local/lib/python3.12/site-packages/airflow/operators/bash.py", line 276, in execute
    raise AirflowException(
airflow.exceptions.AirflowException: Bash command failed. The command returned a non-zero exit code 1.
[2025-04-14T17:22:00.362+0000] {taskinstance.py:1226} INFO - Marking task as UP_FOR_RETRY. dag_id=dbt_***, task_id=run_dbt_marts, run_id=manual__2025-04-14T15:18:53.940263+00:00, execution_date=20250414T151853, start_date=20250414T172141, end_date=20250414T172200
[2025-04-14T17:22:00.397+0000] {taskinstance.py:341} INFO - ::group::Post task execution logs
[2025-04-14T17:22:00.398+0000] {standard_task_runner.py:124} ERROR - Failed to execute job 515 for task run_dbt_marts (Bash command failed. The command returned a non-zero exit code 1.; 13865)
Traceback (most recent call last):
  File "/home/airflow/.local/lib/python3.12/site-packages/airflow/task/task_runner/standard_task_runner.py", line 117, in _start_by_fork
    ret = args.func(args, dag=self.dag)
          ^^^^^^^^^^^^^^^^^^^^^^^^^^^^^
  File "/home/airflow/.local/lib/python3.12/site-packages/airflow/cli/cli_config.py", line 49, in command
    return func(*args, **kwargs)
           ^^^^^^^^^^^^^^^^^^^^^
  File "/home/airflow/.local/lib/python3.12/site-packages/airflow/utils/cli.py", line 116, in wrapper
    return f(*args, **kwargs)
           ^^^^^^^^^^^^^^^^^^
  File "/home/airflow/.local/lib/python3.12/site-packages/airflow/cli/commands/task_command.py", line 483, in task_run
    task_return_code = _run_task_by_selected_method(args, _dag, ti)
                       ^^^^^^^^^^^^^^^^^^^^^^^^^^^^^^^^^^^^^^^^^^^^
  File "/home/airflow/.local/lib/python3.12/site-packages/airflow/cli/commands/task_command.py", line 256, in _run_task_by_selected_method
    return _run_raw_task(args, ti)
           ^^^^^^^^^^^^^^^^^^^^^^^
  File "/home/airflow/.local/lib/python3.12/site-packages/airflow/cli/commands/task_command.py", line 341, in _run_raw_task
    return ti._run_raw_task(
           ^^^^^^^^^^^^^^^^^
  File "/home/airflow/.local/lib/python3.12/site-packages/airflow/utils/session.py", line 97, in wrapper
    return func(*args, session=session, **kwargs)
           ^^^^^^^^^^^^^^^^^^^^^^^^^^^^^^^^^^^^^^
  File "/home/airflow/.local/lib/python3.12/site-packages/airflow/models/taskinstance.py", line 3006, in _run_raw_task
    return _run_raw_task(
           ^^^^^^^^^^^^^^
  File "/home/airflow/.local/lib/python3.12/site-packages/airflow/models/taskinstance.py", line 274, in _run_raw_task
    TaskInstance._execute_task_with_callbacks(
  File "/home/airflow/.local/lib/python3.12/site-packages/airflow/models/taskinstance.py", line 3161, in _execute_task_with_callbacks
    result = self._execute_task(context, task_orig)
             ^^^^^^^^^^^^^^^^^^^^^^^^^^^^^^^^^^^^^^
  File "/home/airflow/.local/lib/python3.12/site-packages/airflow/models/taskinstance.py", line 3185, in _execute_task
    return _execute_task(self, context, task_orig)
           ^^^^^^^^^^^^^^^^^^^^^^^^^^^^^^^^^^^^^^^
  File "/home/airflow/.local/lib/python3.12/site-packages/airflow/models/taskinstance.py", line 768, in _execute_task
    result = _execute_callable(context=context, **execute_callable_kwargs)
             ^^^^^^^^^^^^^^^^^^^^^^^^^^^^^^^^^^^^^^^^^^^^^^^^^^^^^^^^^^^^^
  File "/home/airflow/.local/lib/python3.12/site-packages/airflow/models/taskinstance.py", line 734, in _execute_callable
    return ExecutionCallableRunner(
           ^^^^^^^^^^^^^^^^^^^^^^^^
  File "/home/airflow/.local/lib/python3.12/site-packages/airflow/utils/operator_helpers.py", line 252, in run
    return self.func(*args, **kwargs)
           ^^^^^^^^^^^^^^^^^^^^^^^^^^
  File "/home/airflow/.local/lib/python3.12/site-packages/airflow/models/baseoperator.py", line 424, in wrapper
    return func(self, *args, **kwargs)
           ^^^^^^^^^^^^^^^^^^^^^^^^^^^
  File "/home/airflow/.local/lib/python3.12/site-packages/airflow/operators/bash.py", line 276, in execute
    raise AirflowException(
airflow.exceptions.AirflowException: Bash command failed. The command returned a non-zero exit code 1.
[2025-04-14T17:22:00.409+0000] {local_task_job_runner.py:266} INFO - Task exited with return code 1
[2025-04-14T17:22:00.434+0000] {taskinstance.py:3901} INFO - 0 downstream tasks scheduled from follow-on schedule check
[2025-04-14T17:22:00.437+0000] {local_task_job_runner.py:245} INFO - ::endgroup::
