[2025-04-14T17:29:07.507+0000] {local_task_job_runner.py:123} INFO - ::group::Pre task execution logs
[2025-04-14T17:29:07.528+0000] {taskinstance.py:2614} INFO - Dependencies all met for dep_context=non-requeueable deps ti=<TaskInstance: dbt_airflow.run_dbt_marts manual__2025-04-14T15:18:53.940263+00:00 [queued]>
[2025-04-14T17:29:07.539+0000] {taskinstance.py:2614} INFO - Dependencies all met for dep_context=requeueable deps ti=<TaskInstance: dbt_airflow.run_dbt_marts manual__2025-04-14T15:18:53.940263+00:00 [queued]>
[2025-04-14T17:29:07.540+0000] {taskinstance.py:2867} INFO - Starting attempt 5 of 5
[2025-04-14T17:29:07.556+0000] {taskinstance.py:2890} INFO - Executing <Task(BashOperator): run_dbt_marts> on 2025-04-14 15:18:53.940263+00:00
[2025-04-14T17:29:07.566+0000] {standard_task_runner.py:104} INFO - Running: ['***', 'tasks', 'run', 'dbt_***', 'run_dbt_marts', 'manual__2025-04-14T15:18:53.940263+00:00', '--job-id', '521', '--raw', '--subdir', 'DAGS_FOLDER/run_dbt_model.py', '--cfg-path', '/tmp/tmpludm2qyz']
[2025-04-14T17:29:07.569+0000] {standard_task_runner.py:105} INFO - Job 521: Subtask run_dbt_marts
[2025-04-14T17:29:07.570+0000] {logging_mixin.py:190} WARNING - /home/***/.local/lib/python3.12/site-packages/***/task/task_runner/standard_task_runner.py:70 DeprecationWarning: This process (pid=14317) is multi-threaded, use of fork() may lead to deadlocks in the child.
[2025-04-14T17:29:07.571+0000] {standard_task_runner.py:72} INFO - Started process 14318 to run task
[2025-04-14T17:29:07.619+0000] {task_command.py:467} INFO - Running <TaskInstance: dbt_airflow.run_dbt_marts manual__2025-04-14T15:18:53.940263+00:00 [running]> on host b7be566335ce
[2025-04-14T17:29:07.702+0000] {taskinstance.py:3134} INFO - Exporting env vars: AIRFLOW_CTX_DAG_OWNER='***' AIRFLOW_CTX_DAG_ID='dbt_***' AIRFLOW_CTX_TASK_ID='run_dbt_marts' AIRFLOW_CTX_EXECUTION_DATE='2025-04-14T15:18:53.940263+00:00' AIRFLOW_CTX_TRY_NUMBER='5' AIRFLOW_CTX_DAG_RUN_ID='manual__2025-04-14T15:18:53.940263+00:00'
[2025-04-14T17:29:07.703+0000] {taskinstance.py:732} INFO - ::endgroup::
[2025-04-14T17:29:07.718+0000] {subprocess.py:78} INFO - Tmp dir root location: /tmp
[2025-04-14T17:29:07.720+0000] {subprocess.py:88} INFO - Running command: ['/usr/bin/bash', '-c', 'cd /opt/***/dbt && dbt run --models fact_departures_by_airport_year']
[2025-04-14T17:29:07.729+0000] {subprocess.py:99} INFO - Output:
[2025-04-14T17:29:11.140+0000] {subprocess.py:106} INFO - [0m17:29:11  Running with dbt=1.7.9
[2025-04-14T17:29:12.878+0000] {subprocess.py:106} INFO - [0m17:29:12  Registered adapter: bigquery=1.7.9
[2025-04-14T17:29:13.925+0000] {subprocess.py:106} INFO - [0m17:29:13  Found 1 seed, 3 models, 1 source, 0 exposures, 0 metrics, 571 macros, 0 groups, 0 semantic models
[2025-04-14T17:29:13.929+0000] {subprocess.py:106} INFO - [0m17:29:13
[2025-04-14T17:29:14.719+0000] {subprocess.py:106} INFO - [0m17:29:14  Concurrency: 1 threads (target='dev')
[2025-04-14T17:29:14.720+0000] {subprocess.py:106} INFO - [0m17:29:14
[2025-04-14T17:29:14.733+0000] {subprocess.py:106} INFO - [0m17:29:14  1 of 1 START sql table model db_project_dataset.fact_departures_by_airport_year  [RUN]
[2025-04-14T17:29:15.992+0000] {subprocess.py:106} INFO - [0m17:29:15  BigQuery adapter: https://console.cloud.google.com/bigquery?project=db-project-456518&j=bq:europe-central2:57f194f3-185f-4ab3-b73c-e01f863b113c&page=queryresults
[2025-04-14T17:29:16.005+0000] {subprocess.py:106} INFO - [0m17:29:16  1 of 1 ERROR creating sql table model db_project_dataset.fact_departures_by_airport_year  [[31mERROR[0m in 1.27s]
[2025-04-14T17:29:16.013+0000] {subprocess.py:106} INFO - [0m17:29:16
[2025-04-14T17:29:16.014+0000] {subprocess.py:106} INFO - [0m17:29:16  Finished running 1 table model in 0 hours 0 minutes and 2.08 seconds (2.08s).
[2025-04-14T17:29:16.040+0000] {subprocess.py:106} INFO - [0m17:29:16
[2025-04-14T17:29:16.041+0000] {subprocess.py:106} INFO - [0m17:29:16  [31mCompleted with 1 error and 0 warnings:[0m
[2025-04-14T17:29:16.042+0000] {subprocess.py:106} INFO - [0m17:29:16
[2025-04-14T17:29:16.043+0000] {subprocess.py:106} INFO - [0m17:29:16    Database Error in model fact_departures_by_airport_year (models/marts/fact_departures_by_airport_year.sql)
[2025-04-14T17:29:16.044+0000] {subprocess.py:106} INFO -   No matching signature for function EXTRACT for argument types: DATE_TIME_PART FROM STRING
[2025-04-14T17:29:16.045+0000] {subprocess.py:106} INFO -     Signature: EXTRACT(DATE_TIME_PART FROM DATE)
[2025-04-14T17:29:16.045+0000] {subprocess.py:106} INFO -       Argument 1: Unable to coerce type STRING to expected type DATE
[2025-04-14T17:29:16.046+0000] {subprocess.py:106} INFO -     Signature: EXTRACT(DATE_TIME_PART FROM TIMESTAMP [AT TIME ZONE STRING])
[2025-04-14T17:29:16.047+0000] {subprocess.py:106} INFO -       Argument 1: Unable to coerce type STRING to expected type TIMESTAMP
[2025-04-14T17:29:16.047+0000] {subprocess.py:106} INFO -     Signature: EXTRACT(DATE_TIME_PART FROM DATETIME)
[2025-04-14T17:29:16.048+0000] {subprocess.py:106} INFO -       Argument 1: Unable to coerce type STRING to expected type DATETIME
[2025-04-14T17:29:16.049+0000] {subprocess.py:106} INFO -     Signature: EXTRACT(DATE_TIME_PART FROM TIME)
[2025-04-14T17:29:16.049+0000] {subprocess.py:106} INFO -       Argument 1: Unable to coerce type STRING to expected type TIME
[2025-04-14T17:29:16.050+0000] {subprocess.py:106} INFO -     Signature: EXTRACT(DATE_TIME_PART FROM INTERVAL)
[2025-04-14T17:29:16.051+0000] {subprocess.py:106} INFO -       Argument 1: Unable to coerce type STRING to expected type INTERVAL at [22:5]
[2025-04-14T17:29:16.052+0000] {subprocess.py:106} INFO -   compiled Code at target/run/flights_project/models/marts/fact_departures_by_airport_year.sql
[2025-04-14T17:29:16.052+0000] {subprocess.py:106} INFO - [0m17:29:16
[2025-04-14T17:29:16.053+0000] {subprocess.py:106} INFO - [0m17:29:16  Done. PASS=0 WARN=0 ERROR=1 SKIP=0 TOTAL=1
[2025-04-14T17:29:17.038+0000] {subprocess.py:110} INFO - Command exited with return code 1
[2025-04-14T17:29:17.049+0000] {taskinstance.py:3313} ERROR - Task failed with exception
Traceback (most recent call last):
  File "/home/airflow/.local/lib/python3.12/site-packages/airflow/models/taskinstance.py", line 768, in _execute_task
    result = _execute_callable(context=context, **execute_callable_kwargs)
             ^^^^^^^^^^^^^^^^^^^^^^^^^^^^^^^^^^^^^^^^^^^^^^^^^^^^^^^^^^^^^
  File "/home/airflow/.local/lib/python3.12/site-packages/airflow/models/taskinstance.py", line 734, in _execute_callable
    return ExecutionCallableRunner(
           ^^^^^^^^^^^^^^^^^^^^^^^^
  File "/home/airflow/.local/lib/python3.12/site-packages/airflow/utils/operator_helpers.py", line 252, in run
    return self.func(*args, **kwargs)
           ^^^^^^^^^^^^^^^^^^^^^^^^^^
  File "/home/airflow/.local/lib/python3.12/site-packages/airflow/models/baseoperator.py", line 424, in wrapper
    return func(self, *args, **kwargs)
           ^^^^^^^^^^^^^^^^^^^^^^^^^^^
  File "/home/airflow/.local/lib/python3.12/site-packages/airflow/operators/bash.py", line 276, in execute
    raise AirflowException(
airflow.exceptions.AirflowException: Bash command failed. The command returned a non-zero exit code 1.
[2025-04-14T17:29:17.053+0000] {taskinstance.py:1226} INFO - Marking task as FAILED. dag_id=dbt_***, task_id=run_dbt_marts, run_id=manual__2025-04-14T15:18:53.940263+00:00, execution_date=20250414T151853, start_date=20250414T172907, end_date=20250414T172917
[2025-04-14T17:29:17.083+0000] {taskinstance.py:341} INFO - ::group::Post task execution logs
[2025-04-14T17:29:17.084+0000] {standard_task_runner.py:124} ERROR - Failed to execute job 521 for task run_dbt_marts (Bash command failed. The command returned a non-zero exit code 1.; 14318)
Traceback (most recent call last):
  File "/home/airflow/.local/lib/python3.12/site-packages/airflow/task/task_runner/standard_task_runner.py", line 117, in _start_by_fork
    ret = args.func(args, dag=self.dag)
          ^^^^^^^^^^^^^^^^^^^^^^^^^^^^^
  File "/home/airflow/.local/lib/python3.12/site-packages/airflow/cli/cli_config.py", line 49, in command
    return func(*args, **kwargs)
           ^^^^^^^^^^^^^^^^^^^^^
  File "/home/airflow/.local/lib/python3.12/site-packages/airflow/utils/cli.py", line 116, in wrapper
    return f(*args, **kwargs)
           ^^^^^^^^^^^^^^^^^^
  File "/home/airflow/.local/lib/python3.12/site-packages/airflow/cli/commands/task_command.py", line 483, in task_run
    task_return_code = _run_task_by_selected_method(args, _dag, ti)
                       ^^^^^^^^^^^^^^^^^^^^^^^^^^^^^^^^^^^^^^^^^^^^
  File "/home/airflow/.local/lib/python3.12/site-packages/airflow/cli/commands/task_command.py", line 256, in _run_task_by_selected_method
    return _run_raw_task(args, ti)
           ^^^^^^^^^^^^^^^^^^^^^^^
  File "/home/airflow/.local/lib/python3.12/site-packages/airflow/cli/commands/task_command.py", line 341, in _run_raw_task
    return ti._run_raw_task(
           ^^^^^^^^^^^^^^^^^
  File "/home/airflow/.local/lib/python3.12/site-packages/airflow/utils/session.py", line 97, in wrapper
    return func(*args, session=session, **kwargs)
           ^^^^^^^^^^^^^^^^^^^^^^^^^^^^^^^^^^^^^^
  File "/home/airflow/.local/lib/python3.12/site-packages/airflow/models/taskinstance.py", line 3006, in _run_raw_task
    return _run_raw_task(
           ^^^^^^^^^^^^^^
  File "/home/airflow/.local/lib/python3.12/site-packages/airflow/models/taskinstance.py", line 274, in _run_raw_task
    TaskInstance._execute_task_with_callbacks(
  File "/home/airflow/.local/lib/python3.12/site-packages/airflow/models/taskinstance.py", line 3161, in _execute_task_with_callbacks
    result = self._execute_task(context, task_orig)
             ^^^^^^^^^^^^^^^^^^^^^^^^^^^^^^^^^^^^^^
  File "/home/airflow/.local/lib/python3.12/site-packages/airflow/models/taskinstance.py", line 3185, in _execute_task
    return _execute_task(self, context, task_orig)
           ^^^^^^^^^^^^^^^^^^^^^^^^^^^^^^^^^^^^^^^
  File "/home/airflow/.local/lib/python3.12/site-packages/airflow/models/taskinstance.py", line 768, in _execute_task
    result = _execute_callable(context=context, **execute_callable_kwargs)
             ^^^^^^^^^^^^^^^^^^^^^^^^^^^^^^^^^^^^^^^^^^^^^^^^^^^^^^^^^^^^^
  File "/home/airflow/.local/lib/python3.12/site-packages/airflow/models/taskinstance.py", line 734, in _execute_callable
    return ExecutionCallableRunner(
           ^^^^^^^^^^^^^^^^^^^^^^^^
  File "/home/airflow/.local/lib/python3.12/site-packages/airflow/utils/operator_helpers.py", line 252, in run
    return self.func(*args, **kwargs)
           ^^^^^^^^^^^^^^^^^^^^^^^^^^
  File "/home/airflow/.local/lib/python3.12/site-packages/airflow/models/baseoperator.py", line 424, in wrapper
    return func(self, *args, **kwargs)
           ^^^^^^^^^^^^^^^^^^^^^^^^^^^
  File "/home/airflow/.local/lib/python3.12/site-packages/airflow/operators/bash.py", line 276, in execute
    raise AirflowException(
airflow.exceptions.AirflowException: Bash command failed. The command returned a non-zero exit code 1.
[2025-04-14T17:29:17.117+0000] {local_task_job_runner.py:266} INFO - Task exited with return code 1
[2025-04-14T17:29:17.140+0000] {taskinstance.py:3901} INFO - 0 downstream tasks scheduled from follow-on schedule check
[2025-04-14T17:29:17.143+0000] {local_task_job_runner.py:245} INFO - ::endgroup::
