[2025-04-18T19:57:11.755+0000] {local_task_job_runner.py:123} INFO - ::group::Pre task execution logs
[2025-04-18T19:57:11.805+0000] {taskinstance.py:2614} INFO - Dependencies all met for dep_context=non-requeueable deps ti=<TaskInstance: run_dbt.run_dbt_seed manual__2025-04-18T19:56:57.798037+00:00 [queued]>
[2025-04-18T19:57:11.823+0000] {taskinstance.py:2614} INFO - Dependencies all met for dep_context=requeueable deps ti=<TaskInstance: run_dbt.run_dbt_seed manual__2025-04-18T19:56:57.798037+00:00 [queued]>
[2025-04-18T19:57:11.824+0000] {taskinstance.py:2867} INFO - Starting attempt 1 of 2
[2025-04-18T19:57:11.845+0000] {taskinstance.py:2890} INFO - Executing <Task(BashOperator): run_dbt_seed> on 2025-04-18 19:56:57.798037+00:00
[2025-04-18T19:57:11.854+0000] {logging_mixin.py:190} WARNING - /home/***/.local/lib/python3.12/site-packages/***/task/task_runner/standard_task_runner.py:70 DeprecationWarning: This process (pid=41869) is multi-threaded, use of fork() may lead to deadlocks in the child.
[2025-04-18T19:57:11.856+0000] {standard_task_runner.py:72} INFO - Started process 41870 to run task
[2025-04-18T19:57:11.854+0000] {standard_task_runner.py:104} INFO - Running: ['***', 'tasks', 'run', 'run_dbt', 'run_dbt_seed', 'manual__2025-04-18T19:56:57.798037+00:00', '--job-id', '621', '--raw', '--subdir', 'DAGS_FOLDER/run_dbt_model.py', '--cfg-path', '/tmp/tmp5wfaqdw8']
[2025-04-18T19:57:11.857+0000] {standard_task_runner.py:105} INFO - Job 621: Subtask run_dbt_seed
[2025-04-18T19:57:11.939+0000] {task_command.py:467} INFO - Running <TaskInstance: run_dbt.run_dbt_seed manual__2025-04-18T19:56:57.798037+00:00 [running]> on host f21ba0bbe878
[2025-04-18T19:57:12.039+0000] {taskinstance.py:3134} INFO - Exporting env vars: AIRFLOW_CTX_DAG_OWNER='***' AIRFLOW_CTX_DAG_ID='run_dbt' AIRFLOW_CTX_TASK_ID='run_dbt_seed' AIRFLOW_CTX_EXECUTION_DATE='2025-04-18T19:56:57.798037+00:00' AIRFLOW_CTX_TRY_NUMBER='1' AIRFLOW_CTX_DAG_RUN_ID='manual__2025-04-18T19:56:57.798037+00:00'
[2025-04-18T19:57:12.040+0000] {taskinstance.py:732} INFO - ::endgroup::
[2025-04-18T19:57:12.058+0000] {subprocess.py:78} INFO - Tmp dir root location: /tmp
[2025-04-18T19:57:12.059+0000] {subprocess.py:88} INFO - Running command: ['/usr/bin/bash', '-c', 'cd /opt/***/dbt && dbt seed']
[2025-04-18T19:57:12.069+0000] {subprocess.py:99} INFO - Output:
[2025-04-18T19:57:15.256+0000] {subprocess.py:106} INFO - [0m19:57:15  Running with dbt=1.8.1
[2025-04-18T19:57:16.987+0000] {subprocess.py:106} INFO - [0m19:57:16  Registered adapter: bigquery=1.8.1
[2025-04-18T19:57:17.368+0000] {subprocess.py:106} INFO - [0m19:57:17  Unable to do partial parsing because of a version mismatch
[2025-04-18T19:57:20.385+0000] {subprocess.py:106} INFO - [0m19:57:20  Encountered an error:
[2025-04-18T19:57:20.386+0000] {subprocess.py:106} INFO - Compilation Error in model fact_delays_departure_by_airport (models/marts/fact_delays_departure_by_airport.sql)
[2025-04-18T19:57:20.386+0000] {subprocess.py:106} INFO -   The name argument to ref() must be a string, got <class 'dbt_common.clients.jinja.create_undefined.<locals>.Undefined'>
[2025-04-18T19:57:21.414+0000] {subprocess.py:110} INFO - Command exited with return code 2
[2025-04-18T19:57:21.425+0000] {taskinstance.py:3313} ERROR - Task failed with exception
Traceback (most recent call last):
  File "/home/airflow/.local/lib/python3.12/site-packages/airflow/models/taskinstance.py", line 768, in _execute_task
    result = _execute_callable(context=context, **execute_callable_kwargs)
             ^^^^^^^^^^^^^^^^^^^^^^^^^^^^^^^^^^^^^^^^^^^^^^^^^^^^^^^^^^^^^
  File "/home/airflow/.local/lib/python3.12/site-packages/airflow/models/taskinstance.py", line 734, in _execute_callable
    return ExecutionCallableRunner(
           ^^^^^^^^^^^^^^^^^^^^^^^^
  File "/home/airflow/.local/lib/python3.12/site-packages/airflow/utils/operator_helpers.py", line 252, in run
    return self.func(*args, **kwargs)
           ^^^^^^^^^^^^^^^^^^^^^^^^^^
  File "/home/airflow/.local/lib/python3.12/site-packages/airflow/models/baseoperator.py", line 424, in wrapper
    return func(self, *args, **kwargs)
           ^^^^^^^^^^^^^^^^^^^^^^^^^^^
  File "/home/airflow/.local/lib/python3.12/site-packages/airflow/operators/bash.py", line 276, in execute
    raise AirflowException(
airflow.exceptions.AirflowException: Bash command failed. The command returned a non-zero exit code 2.
[2025-04-18T19:57:21.435+0000] {taskinstance.py:1226} INFO - Marking task as UP_FOR_RETRY. dag_id=run_dbt, task_id=run_dbt_seed, run_id=manual__2025-04-18T19:56:57.798037+00:00, execution_date=20250418T195657, start_date=20250418T195711, end_date=20250418T195721
[2025-04-18T19:57:21.468+0000] {taskinstance.py:341} INFO - ::group::Post task execution logs
[2025-04-18T19:57:21.469+0000] {standard_task_runner.py:124} ERROR - Failed to execute job 621 for task run_dbt_seed (Bash command failed. The command returned a non-zero exit code 2.; 41870)
Traceback (most recent call last):
  File "/home/airflow/.local/lib/python3.12/site-packages/airflow/task/task_runner/standard_task_runner.py", line 117, in _start_by_fork
    ret = args.func(args, dag=self.dag)
          ^^^^^^^^^^^^^^^^^^^^^^^^^^^^^
  File "/home/airflow/.local/lib/python3.12/site-packages/airflow/cli/cli_config.py", line 49, in command
    return func(*args, **kwargs)
           ^^^^^^^^^^^^^^^^^^^^^
  File "/home/airflow/.local/lib/python3.12/site-packages/airflow/utils/cli.py", line 116, in wrapper
    return f(*args, **kwargs)
           ^^^^^^^^^^^^^^^^^^
  File "/home/airflow/.local/lib/python3.12/site-packages/airflow/cli/commands/task_command.py", line 483, in task_run
    task_return_code = _run_task_by_selected_method(args, _dag, ti)
                       ^^^^^^^^^^^^^^^^^^^^^^^^^^^^^^^^^^^^^^^^^^^^
  File "/home/airflow/.local/lib/python3.12/site-packages/airflow/cli/commands/task_command.py", line 256, in _run_task_by_selected_method
    return _run_raw_task(args, ti)
           ^^^^^^^^^^^^^^^^^^^^^^^
  File "/home/airflow/.local/lib/python3.12/site-packages/airflow/cli/commands/task_command.py", line 341, in _run_raw_task
    return ti._run_raw_task(
           ^^^^^^^^^^^^^^^^^
  File "/home/airflow/.local/lib/python3.12/site-packages/airflow/utils/session.py", line 97, in wrapper
    return func(*args, session=session, **kwargs)
           ^^^^^^^^^^^^^^^^^^^^^^^^^^^^^^^^^^^^^^
  File "/home/airflow/.local/lib/python3.12/site-packages/airflow/models/taskinstance.py", line 3006, in _run_raw_task
    return _run_raw_task(
           ^^^^^^^^^^^^^^
  File "/home/airflow/.local/lib/python3.12/site-packages/airflow/models/taskinstance.py", line 274, in _run_raw_task
    TaskInstance._execute_task_with_callbacks(
  File "/home/airflow/.local/lib/python3.12/site-packages/airflow/models/taskinstance.py", line 3161, in _execute_task_with_callbacks
    result = self._execute_task(context, task_orig)
             ^^^^^^^^^^^^^^^^^^^^^^^^^^^^^^^^^^^^^^
  File "/home/airflow/.local/lib/python3.12/site-packages/airflow/models/taskinstance.py", line 3185, in _execute_task
    return _execute_task(self, context, task_orig)
           ^^^^^^^^^^^^^^^^^^^^^^^^^^^^^^^^^^^^^^^
  File "/home/airflow/.local/lib/python3.12/site-packages/airflow/models/taskinstance.py", line 768, in _execute_task
    result = _execute_callable(context=context, **execute_callable_kwargs)
             ^^^^^^^^^^^^^^^^^^^^^^^^^^^^^^^^^^^^^^^^^^^^^^^^^^^^^^^^^^^^^
  File "/home/airflow/.local/lib/python3.12/site-packages/airflow/models/taskinstance.py", line 734, in _execute_callable
    return ExecutionCallableRunner(
           ^^^^^^^^^^^^^^^^^^^^^^^^
  File "/home/airflow/.local/lib/python3.12/site-packages/airflow/utils/operator_helpers.py", line 252, in run
    return self.func(*args, **kwargs)
           ^^^^^^^^^^^^^^^^^^^^^^^^^^
  File "/home/airflow/.local/lib/python3.12/site-packages/airflow/models/baseoperator.py", line 424, in wrapper
    return func(self, *args, **kwargs)
           ^^^^^^^^^^^^^^^^^^^^^^^^^^^
  File "/home/airflow/.local/lib/python3.12/site-packages/airflow/operators/bash.py", line 276, in execute
    raise AirflowException(
airflow.exceptions.AirflowException: Bash command failed. The command returned a non-zero exit code 2.
[2025-04-18T19:57:21.508+0000] {local_task_job_runner.py:266} INFO - Task exited with return code 1
[2025-04-18T19:57:21.535+0000] {taskinstance.py:3901} INFO - 0 downstream tasks scheduled from follow-on schedule check
[2025-04-18T19:57:21.537+0000] {local_task_job_runner.py:245} INFO - ::endgroup::
