[2025-04-13T19:06:32.723+0000] {local_task_job_runner.py:123} INFO - ::group::Pre task execution logs
[2025-04-13T19:06:32.764+0000] {taskinstance.py:2614} INFO - Dependencies all met for dep_context=non-requeueable deps ti=<TaskInstance: gcs_dlt_data_pipeline.download_file scheduled__1987-01-01T00:00:00+00:00 [queued]>
[2025-04-13T19:06:32.780+0000] {taskinstance.py:2614} INFO - Dependencies all met for dep_context=requeueable deps ti=<TaskInstance: gcs_dlt_data_pipeline.download_file scheduled__1987-01-01T00:00:00+00:00 [queued]>
[2025-04-13T19:06:32.781+0000] {taskinstance.py:2867} INFO - Starting attempt 1 of 2
[2025-04-13T19:06:32.832+0000] {taskinstance.py:2890} INFO - Executing <Task(PythonOperator): download_file> on 1987-01-01 00:00:00+00:00
[2025-04-13T19:06:32.869+0000] {standard_task_runner.py:104} INFO - Running: ['***', 'tasks', 'run', 'gcs_dlt_data_pipeline', 'download_file', 'scheduled__1987-01-01T00:00:00+00:00', '--job-id', '129', '--raw', '--subdir', 'DAGS_FOLDER/first_stage/first_stage.py', '--cfg-path', '/tmp/tmp0lvib5rm']
[2025-04-13T19:06:32.891+0000] {standard_task_runner.py:105} INFO - Job 129: Subtask download_file
[2025-04-13T19:06:32.895+0000] {logging_mixin.py:190} WARNING - /home/***/.local/lib/python3.12/site-packages/***/task/task_runner/standard_task_runner.py:70 DeprecationWarning: This process (pid=363) is multi-threaded, use of fork() may lead to deadlocks in the child.
[2025-04-13T19:06:32.898+0000] {standard_task_runner.py:72} INFO - Started process 370 to run task
[2025-04-13T19:06:33.356+0000] {task_command.py:467} INFO - Running <TaskInstance: gcs_dlt_data_pipeline.download_file scheduled__1987-01-01T00:00:00+00:00 [running]> on host 0728476a73c7
[2025-04-13T19:06:34.551+0000] {taskinstance.py:3134} INFO - Exporting env vars: AIRFLOW_CTX_DAG_OWNER='***' AIRFLOW_CTX_DAG_ID='gcs_dlt_data_pipeline' AIRFLOW_CTX_TASK_ID='download_file' AIRFLOW_CTX_EXECUTION_DATE='1987-01-01T00:00:00+00:00' AIRFLOW_CTX_TRY_NUMBER='1' AIRFLOW_CTX_DAG_RUN_ID='scheduled__1987-01-01T00:00:00+00:00'
[2025-04-13T19:06:34.555+0000] {taskinstance.py:732} INFO - ::endgroup::
[2025-04-13T19:06:34.618+0000] {taskinstance.py:3313} ERROR - Task failed with exception
Traceback (most recent call last):
  File "/home/airflow/.local/lib/python3.12/site-packages/airflow/models/taskinstance.py", line 768, in _execute_task
    result = _execute_callable(context=context, **execute_callable_kwargs)
             ^^^^^^^^^^^^^^^^^^^^^^^^^^^^^^^^^^^^^^^^^^^^^^^^^^^^^^^^^^^^^
  File "/home/airflow/.local/lib/python3.12/site-packages/airflow/models/taskinstance.py", line 734, in _execute_callable
    return ExecutionCallableRunner(
           ^^^^^^^^^^^^^^^^^^^^^^^^
  File "/home/airflow/.local/lib/python3.12/site-packages/airflow/utils/operator_helpers.py", line 252, in run
    return self.func(*args, **kwargs)
           ^^^^^^^^^^^^^^^^^^^^^^^^^^
  File "/home/airflow/.local/lib/python3.12/site-packages/airflow/models/baseoperator.py", line 424, in wrapper
    return func(self, *args, **kwargs)
           ^^^^^^^^^^^^^^^^^^^^^^^^^^^
  File "/home/airflow/.local/lib/python3.12/site-packages/airflow/operators/python.py", line 235, in execute
    self.op_kwargs = self.determine_kwargs(context)
                     ^^^^^^^^^^^^^^^^^^^^^^^^^^^^^^
  File "/home/airflow/.local/lib/python3.12/site-packages/airflow/operators/python.py", line 247, in determine_kwargs
    return KeywordParameters.determine(self.python_callable, self.op_args, context).unpacking()
           ^^^^^^^^^^^^^^^^^^^^^^^^^^^^^^^^^^^^^^^^^^^^^^^^^^^^^^^^^^^^^^^^^^^^^^^^
  File "/home/airflow/.local/lib/python3.12/site-packages/airflow/utils/operator_helpers.py", line 168, in determine
    raise ValueError(f"The key {name!r} in args is a part of kwargs and therefore reserved.")
ValueError: The key 'execution_date' in args is a part of kwargs and therefore reserved.
[2025-04-13T19:06:34.707+0000] {taskinstance.py:1226} INFO - Marking task as UP_FOR_RETRY. dag_id=gcs_dlt_data_pipeline, task_id=download_file, run_id=scheduled__1987-01-01T00:00:00+00:00, execution_date=19870101T000000, start_date=20250413T190632, end_date=20250413T190634
[2025-04-13T19:06:34.870+0000] {taskinstance.py:341} INFO - ::group::Post task execution logs
[2025-04-13T19:06:34.872+0000] {standard_task_runner.py:124} ERROR - Failed to execute job 129 for task download_file (The key 'execution_date' in args is a part of kwargs and therefore reserved.; 370)
Traceback (most recent call last):
  File "/home/airflow/.local/lib/python3.12/site-packages/airflow/task/task_runner/standard_task_runner.py", line 117, in _start_by_fork
    ret = args.func(args, dag=self.dag)
          ^^^^^^^^^^^^^^^^^^^^^^^^^^^^^
  File "/home/airflow/.local/lib/python3.12/site-packages/airflow/cli/cli_config.py", line 49, in command
    return func(*args, **kwargs)
           ^^^^^^^^^^^^^^^^^^^^^
  File "/home/airflow/.local/lib/python3.12/site-packages/airflow/utils/cli.py", line 116, in wrapper
    return f(*args, **kwargs)
           ^^^^^^^^^^^^^^^^^^
  File "/home/airflow/.local/lib/python3.12/site-packages/airflow/cli/commands/task_command.py", line 483, in task_run
    task_return_code = _run_task_by_selected_method(args, _dag, ti)
                       ^^^^^^^^^^^^^^^^^^^^^^^^^^^^^^^^^^^^^^^^^^^^
  File "/home/airflow/.local/lib/python3.12/site-packages/airflow/cli/commands/task_command.py", line 256, in _run_task_by_selected_method
    return _run_raw_task(args, ti)
           ^^^^^^^^^^^^^^^^^^^^^^^
  File "/home/airflow/.local/lib/python3.12/site-packages/airflow/cli/commands/task_command.py", line 341, in _run_raw_task
    return ti._run_raw_task(
           ^^^^^^^^^^^^^^^^^
  File "/home/airflow/.local/lib/python3.12/site-packages/airflow/utils/session.py", line 97, in wrapper
    return func(*args, session=session, **kwargs)
           ^^^^^^^^^^^^^^^^^^^^^^^^^^^^^^^^^^^^^^
  File "/home/airflow/.local/lib/python3.12/site-packages/airflow/models/taskinstance.py", line 3006, in _run_raw_task
    return _run_raw_task(
           ^^^^^^^^^^^^^^
  File "/home/airflow/.local/lib/python3.12/site-packages/airflow/models/taskinstance.py", line 274, in _run_raw_task
    TaskInstance._execute_task_with_callbacks(
  File "/home/airflow/.local/lib/python3.12/site-packages/airflow/models/taskinstance.py", line 3161, in _execute_task_with_callbacks
    result = self._execute_task(context, task_orig)
             ^^^^^^^^^^^^^^^^^^^^^^^^^^^^^^^^^^^^^^
  File "/home/airflow/.local/lib/python3.12/site-packages/airflow/models/taskinstance.py", line 3185, in _execute_task
    return _execute_task(self, context, task_orig)
           ^^^^^^^^^^^^^^^^^^^^^^^^^^^^^^^^^^^^^^^
  File "/home/airflow/.local/lib/python3.12/site-packages/airflow/models/taskinstance.py", line 768, in _execute_task
    result = _execute_callable(context=context, **execute_callable_kwargs)
             ^^^^^^^^^^^^^^^^^^^^^^^^^^^^^^^^^^^^^^^^^^^^^^^^^^^^^^^^^^^^^
  File "/home/airflow/.local/lib/python3.12/site-packages/airflow/models/taskinstance.py", line 734, in _execute_callable
    return ExecutionCallableRunner(
           ^^^^^^^^^^^^^^^^^^^^^^^^
  File "/home/airflow/.local/lib/python3.12/site-packages/airflow/utils/operator_helpers.py", line 252, in run
    return self.func(*args, **kwargs)
           ^^^^^^^^^^^^^^^^^^^^^^^^^^
  File "/home/airflow/.local/lib/python3.12/site-packages/airflow/models/baseoperator.py", line 424, in wrapper
    return func(self, *args, **kwargs)
           ^^^^^^^^^^^^^^^^^^^^^^^^^^^
  File "/home/airflow/.local/lib/python3.12/site-packages/airflow/operators/python.py", line 235, in execute
    self.op_kwargs = self.determine_kwargs(context)
                     ^^^^^^^^^^^^^^^^^^^^^^^^^^^^^^
  File "/home/airflow/.local/lib/python3.12/site-packages/airflow/operators/python.py", line 247, in determine_kwargs
    return KeywordParameters.determine(self.python_callable, self.op_args, context).unpacking()
           ^^^^^^^^^^^^^^^^^^^^^^^^^^^^^^^^^^^^^^^^^^^^^^^^^^^^^^^^^^^^^^^^^^^^^^^^
  File "/home/airflow/.local/lib/python3.12/site-packages/airflow/utils/operator_helpers.py", line 168, in determine
    raise ValueError(f"The key {name!r} in args is a part of kwargs and therefore reserved.")
ValueError: The key 'execution_date' in args is a part of kwargs and therefore reserved.
[2025-04-13T19:06:34.943+0000] {local_task_job_runner.py:266} INFO - Task exited with return code 1
[2025-04-13T19:06:35.032+0000] {taskinstance.py:3901} INFO - 0 downstream tasks scheduled from follow-on schedule check
[2025-04-13T19:06:35.035+0000] {local_task_job_runner.py:245} INFO - ::endgroup::
